2024-12-13 17:57:23,530 [INFO] [31m[1mWARNING: This is a development server. Do not use it in a production deployment. Use a production WSGI server instead.[0m
 * Running on http://127.0.0.1:8000
2024-12-13 17:57:23,531 [INFO] [33mPress CTRL+C to quit[0m
2024-12-13 17:57:23,533 [INFO]  * Restarting with stat
2024-12-13 17:57:26,476 [WARNING]  * Debugger is active!
2024-12-13 17:57:26,481 [INFO]  * Debugger PIN: 623-265-763
2024-12-13 17:57:56,251 [DEBUG] Received request: {'file_path': 'C:/Users/kth00/Documents/GitHub/2024_2_GameEngineBase/Team4/Saved/'}
2024-12-13 17:57:56,251 [INFO] File path received: C:/Users/kth00/Documents/GitHub/2024_2_GameEngineBase/Team4/Saved/
2024-12-13 17:57:56,251 [INFO] Starting prediction...
2024-12-13 17:57:56,269 [ERROR] Error during prediction
Traceback (most recent call last):
  File "C:\Users\kth00\Documents\GitHub\2024_2_GameEngineBase\Team4\Content\Dataprocess\server.py", line 45, in predict
    prediction = predict_image(file_path)
  File "C:\Users\kth00\Documents\GitHub\2024_2_GameEngineBase\Team4\Content\Dataprocess\predict.py", line 20, in predict_image
    interpreter = tf.lite.Interpreter(model_path=MODEL_PATH)
  File "C:\Users\kth00\AppData\Local\Programs\Python\Python39\lib\site-packages\tensorflow\lite\python\interpreter.py", line 455, in __init__
    _interpreter_wrapper.CreateWrapperFromFile(
ValueError: Model provided has model identifier '

', should be 'TFL3'

2024-12-13 17:57:56,272 [INFO] 127.0.0.1 - - [13/Dec/2024 17:57:56] "[35m[1mPOST /predict HTTP/1.1[0m" 500 -
2024-12-13 17:57:56,279 [DEBUG] Received request: {'file_path': 'C:/Users/kth00/Documents/GitHub/2024_2_GameEngineBase/Team4/Saved/'}
2024-12-13 17:57:56,280 [INFO] File path received: C:/Users/kth00/Documents/GitHub/2024_2_GameEngineBase/Team4/Saved/
2024-12-13 17:57:56,280 [INFO] Starting prediction...
2024-12-13 17:57:56,286 [ERROR] Error during prediction
Traceback (most recent call last):
  File "C:\Users\kth00\Documents\GitHub\2024_2_GameEngineBase\Team4\Content\Dataprocess\server.py", line 45, in predict
    prediction = predict_image(file_path)
  File "C:\Users\kth00\Documents\GitHub\2024_2_GameEngineBase\Team4\Content\Dataprocess\predict.py", line 20, in predict_image
    interpreter = tf.lite.Interpreter(model_path=MODEL_PATH)
  File "C:\Users\kth00\AppData\Local\Programs\Python\Python39\lib\site-packages\tensorflow\lite\python\interpreter.py", line 455, in __init__
    _interpreter_wrapper.CreateWrapperFromFile(
ValueError: Model provided has model identifier '

', should be 'TFL3'

2024-12-13 17:57:56,287 [INFO] 127.0.0.1 - - [13/Dec/2024 17:57:56] "[35m[1mPOST /predict HTTP/1.1[0m" 500 -
2024-12-13 17:58:55,942 [INFO]  * Detected change in 'C:\\Users\\kth00\\Documents\\GitHub\\2024_2_GameEngineBase\\Team4\\Content\\Dataprocess\\predict.py', reloading
2024-12-13 17:58:56,309 [INFO]  * Restarting with stat
2024-12-13 17:58:59,135 [WARNING]  * Debugger is active!
2024-12-13 17:58:59,139 [INFO]  * Debugger PIN: 623-265-763
2024-12-13 17:59:04,236 [INFO]  * Detected change in 'C:\\Users\\kth00\\Documents\\GitHub\\2024_2_GameEngineBase\\Team4\\Content\\Dataprocess\\predict.py', reloading
2024-12-13 17:59:04,646 [INFO]  * Restarting with stat
2024-12-13 17:59:07,240 [WARNING]  * Debugger is active!
2024-12-13 17:59:07,243 [INFO]  * Debugger PIN: 623-265-763
2024-12-13 17:59:13,502 [DEBUG] Received request: {'file_path': 'C:/Users/kth00/Documents/GitHub/2024_2_GameEngineBase/Team4/Saved/'}
2024-12-13 17:59:13,502 [INFO] File path received: C:/Users/kth00/Documents/GitHub/2024_2_GameEngineBase/Team4/Saved/
2024-12-13 17:59:13,502 [INFO] Starting prediction...
2024-12-13 17:59:13,539 [ERROR] Error during prediction
Traceback (most recent call last):
  File "C:\Users\kth00\Documents\GitHub\2024_2_GameEngineBase\Team4\Content\Dataprocess\predict.py", line 23, in predict_image
    img = load_img(img_path, target_size=(224, 224))
  File "C:\Users\kth00\AppData\Local\Programs\Python\Python39\lib\site-packages\keras\utils\image_utils.py", line 422, in load_img
    with open(path, "rb") as f:
PermissionError: [Errno 13] Permission denied: 'C:/Users/kth00/Documents/GitHub/2024_2_GameEngineBase/Team4/Saved/'

During handling of the above exception, another exception occurred:

Traceback (most recent call last):
  File "C:\Users\kth00\Documents\GitHub\2024_2_GameEngineBase\Team4\Content\Dataprocess\server.py", line 45, in predict
    prediction = predict_image(file_path)
  File "C:\Users\kth00\Documents\GitHub\2024_2_GameEngineBase\Team4\Content\Dataprocess\predict.py", line 36, in predict_image
    raise RuntimeError(f"Prediction failed: {e}")
RuntimeError: Prediction failed: [Errno 13] Permission denied: 'C:/Users/kth00/Documents/GitHub/2024_2_GameEngineBase/Team4/Saved/'
2024-12-13 17:59:13,540 [DEBUG] Received request: {'file_path': 'C:/Users/kth00/Documents/GitHub/2024_2_GameEngineBase/Team4/Saved/'}
2024-12-13 17:59:13,558 [INFO] 127.0.0.1 - - [13/Dec/2024 17:59:13] "[35m[1mPOST /predict HTTP/1.1[0m" 500 -
2024-12-13 17:59:13,559 [INFO] File path received: C:/Users/kth00/Documents/GitHub/2024_2_GameEngineBase/Team4/Saved/
2024-12-13 17:59:13,560 [INFO] Starting prediction...
2024-12-13 17:59:13,581 [ERROR] Error during prediction
Traceback (most recent call last):
  File "C:\Users\kth00\Documents\GitHub\2024_2_GameEngineBase\Team4\Content\Dataprocess\predict.py", line 23, in predict_image
    img = load_img(img_path, target_size=(224, 224))
  File "C:\Users\kth00\AppData\Local\Programs\Python\Python39\lib\site-packages\keras\utils\image_utils.py", line 422, in load_img
    with open(path, "rb") as f:
PermissionError: [Errno 13] Permission denied: 'C:/Users/kth00/Documents/GitHub/2024_2_GameEngineBase/Team4/Saved/'

During handling of the above exception, another exception occurred:

Traceback (most recent call last):
  File "C:\Users\kth00\Documents\GitHub\2024_2_GameEngineBase\Team4\Content\Dataprocess\server.py", line 45, in predict
    prediction = predict_image(file_path)
  File "C:\Users\kth00\Documents\GitHub\2024_2_GameEngineBase\Team4\Content\Dataprocess\predict.py", line 36, in predict_image
    raise RuntimeError(f"Prediction failed: {e}")
RuntimeError: Prediction failed: [Errno 13] Permission denied: 'C:/Users/kth00/Documents/GitHub/2024_2_GameEngineBase/Team4/Saved/'
2024-12-13 17:59:13,584 [INFO] 127.0.0.1 - - [13/Dec/2024 17:59:13] "[35m[1mPOST /predict HTTP/1.1[0m" 500 -
2024-12-13 17:59:23,798 [DEBUG] Received request: {'file_path': 'C:/Users/kth00/Documents/GitHub/2024_2_GameEngineBase/Team4/Saved/'}
2024-12-13 17:59:23,799 [INFO] File path received: C:/Users/kth00/Documents/GitHub/2024_2_GameEngineBase/Team4/Saved/
2024-12-13 17:59:23,799 [INFO] Starting prediction...
2024-12-13 17:59:23,816 [ERROR] Error during prediction
Traceback (most recent call last):
  File "C:\Users\kth00\Documents\GitHub\2024_2_GameEngineBase\Team4\Content\Dataprocess\predict.py", line 23, in predict_image
    img = load_img(img_path, target_size=(224, 224))
  File "C:\Users\kth00\AppData\Local\Programs\Python\Python39\lib\site-packages\keras\utils\image_utils.py", line 422, in load_img
    with open(path, "rb") as f:
PermissionError: [Errno 13] Permission denied: 'C:/Users/kth00/Documents/GitHub/2024_2_GameEngineBase/Team4/Saved/'

During handling of the above exception, another exception occurred:

Traceback (most recent call last):
  File "C:\Users\kth00\Documents\GitHub\2024_2_GameEngineBase\Team4\Content\Dataprocess\server.py", line 45, in predict
    prediction = predict_image(file_path)
  File "C:\Users\kth00\Documents\GitHub\2024_2_GameEngineBase\Team4\Content\Dataprocess\predict.py", line 36, in predict_image
    raise RuntimeError(f"Prediction failed: {e}")
RuntimeError: Prediction failed: [Errno 13] Permission denied: 'C:/Users/kth00/Documents/GitHub/2024_2_GameEngineBase/Team4/Saved/'
2024-12-13 17:59:23,820 [INFO] 127.0.0.1 - - [13/Dec/2024 17:59:23] "[35m[1mPOST /predict HTTP/1.1[0m" 500 -
2024-12-13 17:59:23,867 [DEBUG] Received request: {'file_path': 'C:/Users/kth00/Documents/GitHub/2024_2_GameEngineBase/Team4/Saved/'}
2024-12-13 17:59:23,868 [INFO] File path received: C:/Users/kth00/Documents/GitHub/2024_2_GameEngineBase/Team4/Saved/
2024-12-13 17:59:23,868 [INFO] Starting prediction...
2024-12-13 17:59:23,882 [ERROR] Error during prediction
Traceback (most recent call last):
  File "C:\Users\kth00\Documents\GitHub\2024_2_GameEngineBase\Team4\Content\Dataprocess\predict.py", line 23, in predict_image
    img = load_img(img_path, target_size=(224, 224))
  File "C:\Users\kth00\AppData\Local\Programs\Python\Python39\lib\site-packages\keras\utils\image_utils.py", line 422, in load_img
    with open(path, "rb") as f:
PermissionError: [Errno 13] Permission denied: 'C:/Users/kth00/Documents/GitHub/2024_2_GameEngineBase/Team4/Saved/'

During handling of the above exception, another exception occurred:

Traceback (most recent call last):
  File "C:\Users\kth00\Documents\GitHub\2024_2_GameEngineBase\Team4\Content\Dataprocess\server.py", line 45, in predict
    prediction = predict_image(file_path)
  File "C:\Users\kth00\Documents\GitHub\2024_2_GameEngineBase\Team4\Content\Dataprocess\predict.py", line 36, in predict_image
    raise RuntimeError(f"Prediction failed: {e}")
RuntimeError: Prediction failed: [Errno 13] Permission denied: 'C:/Users/kth00/Documents/GitHub/2024_2_GameEngineBase/Team4/Saved/'
2024-12-13 17:59:23,886 [INFO] 127.0.0.1 - - [13/Dec/2024 17:59:23] "[35m[1mPOST /predict HTTP/1.1[0m" 500 -
2024-12-13 18:01:29,326 [INFO]  * Detected change in 'C:\\Users\\kth00\\Documents\\GitHub\\2024_2_GameEngineBase\\Team4\\Content\\Dataprocess\\server.py', reloading
2024-12-13 18:01:33,559 [INFO] [31m[1mWARNING: This is a development server. Do not use it in a production deployment. Use a production WSGI server instead.[0m
 * Running on http://127.0.0.1:8000
2024-12-13 18:01:33,559 [INFO] [33mPress CTRL+C to quit[0m
2024-12-13 18:01:33,562 [INFO]  * Restarting with stat
2024-12-13 18:01:35,868 [WARNING]  * Debugger is active!
2024-12-13 18:01:35,874 [INFO]  * Debugger PIN: 623-265-763
2024-12-13 18:01:42,228 [DEBUG] Received request: {'file_path': 'C:/Users/kth00/Documents/GitHub/2024_2_GameEngineBase/Team4/Saved/'}
2024-12-13 18:01:42,228 [INFO] File path received: C:/Users/kth00/Documents/GitHub/2024_2_GameEngineBase/Team4/Saved/SavedDrawing.png
2024-12-13 18:01:42,229 [INFO] Starting prediction...
2024-12-13 18:01:42,258 [DEBUG] Received request: {'file_path': 'C:/Users/kth00/Documents/GitHub/2024_2_GameEngineBase/Team4/Saved/'}
2024-12-13 18:01:42,259 [INFO] File path received: C:/Users/kth00/Documents/GitHub/2024_2_GameEngineBase/Team4/Saved/SavedDrawing.png
2024-12-13 18:01:42,259 [INFO] Starting prediction...
2024-12-13 18:01:42,354 [DEBUG] STREAM b'IHDR' 16 13
2024-12-13 18:01:42,355 [DEBUG] STREAM b'IHDR' 16 13
2024-12-13 18:01:42,355 [DEBUG] STREAM b'IDAT' 41 8192
2024-12-13 18:01:42,355 [DEBUG] STREAM b'IDAT' 41 8192
2024-12-13 18:01:42,405 [INFO] Prediction result: K
2024-12-13 18:01:42,410 [INFO] Prediction result: K
2024-12-13 18:01:42,411 [INFO] 127.0.0.1 - - [13/Dec/2024 18:01:42] "POST /predict HTTP/1.1" 200 -
2024-12-13 18:01:42,411 [INFO] 127.0.0.1 - - [13/Dec/2024 18:01:42] "POST /predict HTTP/1.1" 200 -
2024-12-13 18:01:55,190 [DEBUG] Received request: {'file_path': 'C:/Users/kth00/Documents/GitHub/2024_2_GameEngineBase/Team4/Saved/'}
2024-12-13 18:01:55,191 [INFO] File path received: C:/Users/kth00/Documents/GitHub/2024_2_GameEngineBase/Team4/Saved/SavedDrawing.png
2024-12-13 18:01:55,191 [INFO] Starting prediction...
2024-12-13 18:01:55,207 [DEBUG] STREAM b'IHDR' 16 13
2024-12-13 18:01:55,208 [DEBUG] STREAM b'IDAT' 41 8192
2024-12-13 18:01:55,240 [INFO] Prediction result: K
2024-12-13 18:01:55,240 [INFO] 127.0.0.1 - - [13/Dec/2024 18:01:55] "POST /predict HTTP/1.1" 200 -
2024-12-13 18:01:59,309 [DEBUG] Received request: {'file_path': 'C:/Users/kth00/Documents/GitHub/2024_2_GameEngineBase/Team4/Saved/'}
2024-12-13 18:01:59,310 [INFO] File path received: C:/Users/kth00/Documents/GitHub/2024_2_GameEngineBase/Team4/Saved/SavedDrawing.png
2024-12-13 18:01:59,310 [INFO] Starting prediction...
2024-12-13 18:01:59,325 [DEBUG] STREAM b'IHDR' 16 13
2024-12-13 18:01:59,326 [DEBUG] STREAM b'IDAT' 41 8192
2024-12-13 18:01:59,372 [INFO] Prediction result: K
2024-12-13 18:01:59,373 [INFO] 127.0.0.1 - - [13/Dec/2024 18:01:59] "POST /predict HTTP/1.1" 200 -
2024-12-13 18:04:12,266 [DEBUG] Received request: {'file_path': 'C:/Users/kth00/Documents/GitHub/2024_2_GameEngineBase/Team4/Saved/'}
2024-12-13 18:04:12,267 [INFO] File path received: C:/Users/kth00/Documents/GitHub/2024_2_GameEngineBase/Team4/Saved/SavedDrawing.png
2024-12-13 18:04:12,267 [INFO] Starting prediction...
2024-12-13 18:04:12,293 [ERROR] Error during prediction
Traceback (most recent call last):
  File "C:\Users\kth00\Documents\GitHub\2024_2_GameEngineBase\Team4\Content\Dataprocess\predict.py", line 23, in predict_image
    img = load_img(img_path, target_size=(224, 224))
  File "C:\Users\kth00\AppData\Local\Programs\Python\Python39\lib\site-packages\keras\utils\image_utils.py", line 422, in load_img
    with open(path, "rb") as f:
PermissionError: [Errno 13] Permission denied: 'C:/Users/kth00/Documents/GitHub/2024_2_GameEngineBase/Team4/Saved/SavedDrawing.png'

During handling of the above exception, another exception occurred:

Traceback (most recent call last):
  File "C:\Users\kth00\Documents\GitHub\2024_2_GameEngineBase\Team4\Content\Dataprocess\server.py", line 45, in predict
    prediction = predict_image(file_path)
  File "C:\Users\kth00\Documents\GitHub\2024_2_GameEngineBase\Team4\Content\Dataprocess\predict.py", line 36, in predict_image
    raise RuntimeError(f"Prediction failed: {e}")
RuntimeError: Prediction failed: [Errno 13] Permission denied: 'C:/Users/kth00/Documents/GitHub/2024_2_GameEngineBase/Team4/Saved/SavedDrawing.png'
2024-12-13 18:04:12,297 [INFO] 127.0.0.1 - - [13/Dec/2024 18:04:12] "[35m[1mPOST /predict HTTP/1.1[0m" 500 -
2024-12-13 18:04:12,347 [DEBUG] Received request: {'file_path': 'C:/Users/kth00/Documents/GitHub/2024_2_GameEngineBase/Team4/Saved/'}
2024-12-13 18:04:12,347 [INFO] File path received: C:/Users/kth00/Documents/GitHub/2024_2_GameEngineBase/Team4/Saved/SavedDrawing.png
2024-12-13 18:04:12,348 [INFO] Starting prediction...
2024-12-13 18:04:12,364 [DEBUG] STREAM b'IHDR' 16 13
2024-12-13 18:04:12,365 [DEBUG] STREAM b'IDAT' 41 8192
2024-12-13 18:04:12,396 [INFO] Prediction result: K
2024-12-13 18:04:12,397 [INFO] 127.0.0.1 - - [13/Dec/2024 18:04:12] "POST /predict HTTP/1.1" 200 -
2024-12-13 18:04:16,193 [DEBUG] Received request: {'file_path': 'C:/Users/kth00/Documents/GitHub/2024_2_GameEngineBase/Team4/Saved/'}
2024-12-13 18:04:16,193 [INFO] File path received: C:/Users/kth00/Documents/GitHub/2024_2_GameEngineBase/Team4/Saved/SavedDrawing.png
2024-12-13 18:04:16,194 [INFO] Starting prediction...
2024-12-13 18:04:16,209 [ERROR] Error during prediction
Traceback (most recent call last):
  File "C:\Users\kth00\Documents\GitHub\2024_2_GameEngineBase\Team4\Content\Dataprocess\predict.py", line 23, in predict_image
    img = load_img(img_path, target_size=(224, 224))
  File "C:\Users\kth00\AppData\Local\Programs\Python\Python39\lib\site-packages\keras\utils\image_utils.py", line 422, in load_img
    with open(path, "rb") as f:
PermissionError: [Errno 13] Permission denied: 'C:/Users/kth00/Documents/GitHub/2024_2_GameEngineBase/Team4/Saved/SavedDrawing.png'

During handling of the above exception, another exception occurred:

Traceback (most recent call last):
  File "C:\Users\kth00\Documents\GitHub\2024_2_GameEngineBase\Team4\Content\Dataprocess\server.py", line 45, in predict
    prediction = predict_image(file_path)
  File "C:\Users\kth00\Documents\GitHub\2024_2_GameEngineBase\Team4\Content\Dataprocess\predict.py", line 36, in predict_image
    raise RuntimeError(f"Prediction failed: {e}")
RuntimeError: Prediction failed: [Errno 13] Permission denied: 'C:/Users/kth00/Documents/GitHub/2024_2_GameEngineBase/Team4/Saved/SavedDrawing.png'
2024-12-13 18:04:16,212 [INFO] 127.0.0.1 - - [13/Dec/2024 18:04:16] "[35m[1mPOST /predict HTTP/1.1[0m" 500 -
2024-12-13 18:04:16,260 [DEBUG] Received request: {'file_path': 'C:/Users/kth00/Documents/GitHub/2024_2_GameEngineBase/Team4/Saved/'}
2024-12-13 18:04:16,260 [INFO] File path received: C:/Users/kth00/Documents/GitHub/2024_2_GameEngineBase/Team4/Saved/SavedDrawing.png
2024-12-13 18:04:16,261 [INFO] Starting prediction...
2024-12-13 18:04:16,275 [ERROR] Error during prediction
Traceback (most recent call last):
  File "C:\Users\kth00\Documents\GitHub\2024_2_GameEngineBase\Team4\Content\Dataprocess\predict.py", line 23, in predict_image
    img = load_img(img_path, target_size=(224, 224))
  File "C:\Users\kth00\AppData\Local\Programs\Python\Python39\lib\site-packages\keras\utils\image_utils.py", line 422, in load_img
    with open(path, "rb") as f:
PermissionError: [Errno 13] Permission denied: 'C:/Users/kth00/Documents/GitHub/2024_2_GameEngineBase/Team4/Saved/SavedDrawing.png'

During handling of the above exception, another exception occurred:

Traceback (most recent call last):
  File "C:\Users\kth00\Documents\GitHub\2024_2_GameEngineBase\Team4\Content\Dataprocess\server.py", line 45, in predict
    prediction = predict_image(file_path)
  File "C:\Users\kth00\Documents\GitHub\2024_2_GameEngineBase\Team4\Content\Dataprocess\predict.py", line 36, in predict_image
    raise RuntimeError(f"Prediction failed: {e}")
RuntimeError: Prediction failed: [Errno 13] Permission denied: 'C:/Users/kth00/Documents/GitHub/2024_2_GameEngineBase/Team4/Saved/SavedDrawing.png'
2024-12-13 18:04:16,278 [INFO] 127.0.0.1 - - [13/Dec/2024 18:04:16] "[35m[1mPOST /predict HTTP/1.1[0m" 500 -
2024-12-13 18:04:16,327 [DEBUG] Received request: {'file_path': 'C:/Users/kth00/Documents/GitHub/2024_2_GameEngineBase/Team4/Saved/'}
2024-12-13 18:04:16,328 [INFO] File path received: C:/Users/kth00/Documents/GitHub/2024_2_GameEngineBase/Team4/Saved/SavedDrawing.png
2024-12-13 18:04:16,328 [INFO] Starting prediction...
2024-12-13 18:04:16,345 [DEBUG] STREAM b'IHDR' 16 13
2024-12-13 18:04:16,345 [DEBUG] STREAM b'IDAT' 41 8192
2024-12-13 18:04:16,379 [INFO] Prediction result: K
2024-12-13 18:04:16,380 [INFO] 127.0.0.1 - - [13/Dec/2024 18:04:16] "POST /predict HTTP/1.1" 200 -
2024-12-13 18:04:16,729 [DEBUG] Received request: {'file_path': 'C:/Users/kth00/Documents/GitHub/2024_2_GameEngineBase/Team4/Saved/'}
2024-12-13 18:04:16,729 [INFO] File path received: C:/Users/kth00/Documents/GitHub/2024_2_GameEngineBase/Team4/Saved/SavedDrawing.png
2024-12-13 18:04:16,730 [INFO] Starting prediction...
2024-12-13 18:04:16,743 [ERROR] Error during prediction
Traceback (most recent call last):
  File "C:\Users\kth00\Documents\GitHub\2024_2_GameEngineBase\Team4\Content\Dataprocess\predict.py", line 23, in predict_image
    img = load_img(img_path, target_size=(224, 224))
  File "C:\Users\kth00\AppData\Local\Programs\Python\Python39\lib\site-packages\keras\utils\image_utils.py", line 422, in load_img
    with open(path, "rb") as f:
PermissionError: [Errno 13] Permission denied: 'C:/Users/kth00/Documents/GitHub/2024_2_GameEngineBase/Team4/Saved/SavedDrawing.png'

During handling of the above exception, another exception occurred:

Traceback (most recent call last):
  File "C:\Users\kth00\Documents\GitHub\2024_2_GameEngineBase\Team4\Content\Dataprocess\server.py", line 45, in predict
    prediction = predict_image(file_path)
  File "C:\Users\kth00\Documents\GitHub\2024_2_GameEngineBase\Team4\Content\Dataprocess\predict.py", line 36, in predict_image
    raise RuntimeError(f"Prediction failed: {e}")
RuntimeError: Prediction failed: [Errno 13] Permission denied: 'C:/Users/kth00/Documents/GitHub/2024_2_GameEngineBase/Team4/Saved/SavedDrawing.png'
2024-12-13 18:04:16,746 [INFO] 127.0.0.1 - - [13/Dec/2024 18:04:16] "[35m[1mPOST /predict HTTP/1.1[0m" 500 -
2024-12-13 18:04:16,758 [DEBUG] Received request: {'file_path': 'C:/Users/kth00/Documents/GitHub/2024_2_GameEngineBase/Team4/Saved/'}
2024-12-13 18:04:16,759 [INFO] File path received: C:/Users/kth00/Documents/GitHub/2024_2_GameEngineBase/Team4/Saved/SavedDrawing.png
2024-12-13 18:04:16,759 [INFO] Starting prediction...
2024-12-13 18:04:16,774 [ERROR] Error during prediction
Traceback (most recent call last):
  File "C:\Users\kth00\Documents\GitHub\2024_2_GameEngineBase\Team4\Content\Dataprocess\predict.py", line 23, in predict_image
    img = load_img(img_path, target_size=(224, 224))
  File "C:\Users\kth00\AppData\Local\Programs\Python\Python39\lib\site-packages\keras\utils\image_utils.py", line 422, in load_img
    with open(path, "rb") as f:
PermissionError: [Errno 13] Permission denied: 'C:/Users/kth00/Documents/GitHub/2024_2_GameEngineBase/Team4/Saved/SavedDrawing.png'

During handling of the above exception, another exception occurred:

Traceback (most recent call last):
  File "C:\Users\kth00\Documents\GitHub\2024_2_GameEngineBase\Team4\Content\Dataprocess\server.py", line 45, in predict
    prediction = predict_image(file_path)
  File "C:\Users\kth00\Documents\GitHub\2024_2_GameEngineBase\Team4\Content\Dataprocess\predict.py", line 36, in predict_image
    raise RuntimeError(f"Prediction failed: {e}")
RuntimeError: Prediction failed: [Errno 13] Permission denied: 'C:/Users/kth00/Documents/GitHub/2024_2_GameEngineBase/Team4/Saved/SavedDrawing.png'
2024-12-13 18:04:16,777 [INFO] 127.0.0.1 - - [13/Dec/2024 18:04:16] "[35m[1mPOST /predict HTTP/1.1[0m" 500 -
2024-12-13 18:04:16,825 [DEBUG] Received request: {'file_path': 'C:/Users/kth00/Documents/GitHub/2024_2_GameEngineBase/Team4/Saved/'}
2024-12-13 18:04:16,825 [INFO] File path received: C:/Users/kth00/Documents/GitHub/2024_2_GameEngineBase/Team4/Saved/SavedDrawing.png
2024-12-13 18:04:16,826 [INFO] Starting prediction...
2024-12-13 18:04:16,844 [DEBUG] STREAM b'IHDR' 16 13
2024-12-13 18:04:16,844 [DEBUG] STREAM b'IDAT' 41 8192
2024-12-13 18:04:16,872 [INFO] Prediction result: K
2024-12-13 18:04:16,873 [INFO] 127.0.0.1 - - [13/Dec/2024 18:04:16] "POST /predict HTTP/1.1" 200 -
2024-12-13 18:04:16,957 [DEBUG] Received request: {'file_path': 'C:/Users/kth00/Documents/GitHub/2024_2_GameEngineBase/Team4/Saved/'}
2024-12-13 18:04:16,958 [INFO] File path received: C:/Users/kth00/Documents/GitHub/2024_2_GameEngineBase/Team4/Saved/SavedDrawing.png
2024-12-13 18:04:16,962 [INFO] Starting prediction...
2024-12-13 18:04:16,988 [ERROR] Error during prediction
Traceback (most recent call last):
  File "C:\Users\kth00\Documents\GitHub\2024_2_GameEngineBase\Team4\Content\Dataprocess\predict.py", line 23, in predict_image
    img = load_img(img_path, target_size=(224, 224))
  File "C:\Users\kth00\AppData\Local\Programs\Python\Python39\lib\site-packages\keras\utils\image_utils.py", line 422, in load_img
    with open(path, "rb") as f:
PermissionError: [Errno 13] Permission denied: 'C:/Users/kth00/Documents/GitHub/2024_2_GameEngineBase/Team4/Saved/SavedDrawing.png'

During handling of the above exception, another exception occurred:

Traceback (most recent call last):
  File "C:\Users\kth00\Documents\GitHub\2024_2_GameEngineBase\Team4\Content\Dataprocess\server.py", line 45, in predict
    prediction = predict_image(file_path)
  File "C:\Users\kth00\Documents\GitHub\2024_2_GameEngineBase\Team4\Content\Dataprocess\predict.py", line 36, in predict_image
    raise RuntimeError(f"Prediction failed: {e}")
RuntimeError: Prediction failed: [Errno 13] Permission denied: 'C:/Users/kth00/Documents/GitHub/2024_2_GameEngineBase/Team4/Saved/SavedDrawing.png'
2024-12-13 18:04:16,992 [INFO] 127.0.0.1 - - [13/Dec/2024 18:04:16] "[35m[1mPOST /predict HTTP/1.1[0m" 500 -
2024-12-13 18:04:17,038 [DEBUG] Received request: {'file_path': 'C:/Users/kth00/Documents/GitHub/2024_2_GameEngineBase/Team4/Saved/'}
2024-12-13 18:04:17,038 [INFO] File path received: C:/Users/kth00/Documents/GitHub/2024_2_GameEngineBase/Team4/Saved/SavedDrawing.png
2024-12-13 18:04:17,038 [INFO] Starting prediction...
2024-12-13 18:04:17,058 [DEBUG] STREAM b'IHDR' 16 13
2024-12-13 18:04:17,059 [DEBUG] STREAM b'IDAT' 41 8192
2024-12-13 18:04:17,089 [INFO] Prediction result: K
2024-12-13 18:04:17,089 [INFO] 127.0.0.1 - - [13/Dec/2024 18:04:17] "POST /predict HTTP/1.1" 200 -
2024-12-13 18:04:17,167 [DEBUG] Received request: {'file_path': 'C:/Users/kth00/Documents/GitHub/2024_2_GameEngineBase/Team4/Saved/'}
2024-12-13 18:04:17,169 [INFO] File path received: C:/Users/kth00/Documents/GitHub/2024_2_GameEngineBase/Team4/Saved/SavedDrawing.png
2024-12-13 18:04:17,169 [INFO] Starting prediction...
2024-12-13 18:04:17,186 [ERROR] Error during prediction
Traceback (most recent call last):
  File "C:\Users\kth00\Documents\GitHub\2024_2_GameEngineBase\Team4\Content\Dataprocess\predict.py", line 23, in predict_image
    img = load_img(img_path, target_size=(224, 224))
  File "C:\Users\kth00\AppData\Local\Programs\Python\Python39\lib\site-packages\keras\utils\image_utils.py", line 422, in load_img
    with open(path, "rb") as f:
PermissionError: [Errno 13] Permission denied: 'C:/Users/kth00/Documents/GitHub/2024_2_GameEngineBase/Team4/Saved/SavedDrawing.png'

During handling of the above exception, another exception occurred:

Traceback (most recent call last):
  File "C:\Users\kth00\Documents\GitHub\2024_2_GameEngineBase\Team4\Content\Dataprocess\server.py", line 45, in predict
    prediction = predict_image(file_path)
  File "C:\Users\kth00\Documents\GitHub\2024_2_GameEngineBase\Team4\Content\Dataprocess\predict.py", line 36, in predict_image
    raise RuntimeError(f"Prediction failed: {e}")
RuntimeError: Prediction failed: [Errno 13] Permission denied: 'C:/Users/kth00/Documents/GitHub/2024_2_GameEngineBase/Team4/Saved/SavedDrawing.png'
2024-12-13 18:04:17,189 [INFO] 127.0.0.1 - - [13/Dec/2024 18:04:17] "[35m[1mPOST /predict HTTP/1.1[0m" 500 -
2024-12-13 18:04:17,203 [DEBUG] Received request: {'file_path': 'C:/Users/kth00/Documents/GitHub/2024_2_GameEngineBase/Team4/Saved/'}
2024-12-13 18:04:17,204 [INFO] File path received: C:/Users/kth00/Documents/GitHub/2024_2_GameEngineBase/Team4/Saved/SavedDrawing.png
2024-12-13 18:04:17,204 [INFO] Starting prediction...
2024-12-13 18:04:17,220 [ERROR] Error during prediction
Traceback (most recent call last):
  File "C:\Users\kth00\Documents\GitHub\2024_2_GameEngineBase\Team4\Content\Dataprocess\predict.py", line 23, in predict_image
    img = load_img(img_path, target_size=(224, 224))
  File "C:\Users\kth00\AppData\Local\Programs\Python\Python39\lib\site-packages\keras\utils\image_utils.py", line 422, in load_img
    with open(path, "rb") as f:
PermissionError: [Errno 13] Permission denied: 'C:/Users/kth00/Documents/GitHub/2024_2_GameEngineBase/Team4/Saved/SavedDrawing.png'

During handling of the above exception, another exception occurred:

Traceback (most recent call last):
  File "C:\Users\kth00\Documents\GitHub\2024_2_GameEngineBase\Team4\Content\Dataprocess\server.py", line 45, in predict
    prediction = predict_image(file_path)
  File "C:\Users\kth00\Documents\GitHub\2024_2_GameEngineBase\Team4\Content\Dataprocess\predict.py", line 36, in predict_image
    raise RuntimeError(f"Prediction failed: {e}")
RuntimeError: Prediction failed: [Errno 13] Permission denied: 'C:/Users/kth00/Documents/GitHub/2024_2_GameEngineBase/Team4/Saved/SavedDrawing.png'
2024-12-13 18:04:17,223 [INFO] 127.0.0.1 - - [13/Dec/2024 18:04:17] "[35m[1mPOST /predict HTTP/1.1[0m" 500 -
2024-12-13 18:04:17,271 [DEBUG] Received request: {'file_path': 'C:/Users/kth00/Documents/GitHub/2024_2_GameEngineBase/Team4/Saved/'}
2024-12-13 18:04:17,271 [INFO] File path received: C:/Users/kth00/Documents/GitHub/2024_2_GameEngineBase/Team4/Saved/SavedDrawing.png
2024-12-13 18:04:17,271 [INFO] Starting prediction...
2024-12-13 18:04:17,287 [DEBUG] STREAM b'IHDR' 16 13
2024-12-13 18:04:17,287 [DEBUG] STREAM b'IDAT' 41 8192
2024-12-13 18:04:17,314 [INFO] Prediction result: K
2024-12-13 18:04:17,315 [INFO] 127.0.0.1 - - [13/Dec/2024 18:04:17] "POST /predict HTTP/1.1" 200 -
2024-12-13 18:04:17,361 [DEBUG] Received request: {'file_path': 'C:/Users/kth00/Documents/GitHub/2024_2_GameEngineBase/Team4/Saved/'}
2024-12-13 18:04:17,362 [INFO] File path received: C:/Users/kth00/Documents/GitHub/2024_2_GameEngineBase/Team4/Saved/SavedDrawing.png
2024-12-13 18:04:17,362 [INFO] Starting prediction...
2024-12-13 18:04:17,378 [ERROR] Error during prediction
Traceback (most recent call last):
  File "C:\Users\kth00\Documents\GitHub\2024_2_GameEngineBase\Team4\Content\Dataprocess\predict.py", line 23, in predict_image
    img = load_img(img_path, target_size=(224, 224))
  File "C:\Users\kth00\AppData\Local\Programs\Python\Python39\lib\site-packages\keras\utils\image_utils.py", line 422, in load_img
    with open(path, "rb") as f:
PermissionError: [Errno 13] Permission denied: 'C:/Users/kth00/Documents/GitHub/2024_2_GameEngineBase/Team4/Saved/SavedDrawing.png'

During handling of the above exception, another exception occurred:

Traceback (most recent call last):
  File "C:\Users\kth00\Documents\GitHub\2024_2_GameEngineBase\Team4\Content\Dataprocess\server.py", line 45, in predict
    prediction = predict_image(file_path)
  File "C:\Users\kth00\Documents\GitHub\2024_2_GameEngineBase\Team4\Content\Dataprocess\predict.py", line 36, in predict_image
    raise RuntimeError(f"Prediction failed: {e}")
RuntimeError: Prediction failed: [Errno 13] Permission denied: 'C:/Users/kth00/Documents/GitHub/2024_2_GameEngineBase/Team4/Saved/SavedDrawing.png'
2024-12-13 18:04:17,381 [INFO] 127.0.0.1 - - [13/Dec/2024 18:04:17] "[35m[1mPOST /predict HTTP/1.1[0m" 500 -
2024-12-13 18:04:17,427 [DEBUG] Received request: {'file_path': 'C:/Users/kth00/Documents/GitHub/2024_2_GameEngineBase/Team4/Saved/'}
2024-12-13 18:04:17,427 [INFO] File path received: C:/Users/kth00/Documents/GitHub/2024_2_GameEngineBase/Team4/Saved/SavedDrawing.png
2024-12-13 18:04:17,428 [INFO] Starting prediction...
2024-12-13 18:04:17,440 [ERROR] Error during prediction
Traceback (most recent call last):
  File "C:\Users\kth00\Documents\GitHub\2024_2_GameEngineBase\Team4\Content\Dataprocess\predict.py", line 23, in predict_image
    img = load_img(img_path, target_size=(224, 224))
  File "C:\Users\kth00\AppData\Local\Programs\Python\Python39\lib\site-packages\keras\utils\image_utils.py", line 422, in load_img
    with open(path, "rb") as f:
PermissionError: [Errno 13] Permission denied: 'C:/Users/kth00/Documents/GitHub/2024_2_GameEngineBase/Team4/Saved/SavedDrawing.png'

During handling of the above exception, another exception occurred:

Traceback (most recent call last):
  File "C:\Users\kth00\Documents\GitHub\2024_2_GameEngineBase\Team4\Content\Dataprocess\server.py", line 45, in predict
    prediction = predict_image(file_path)
  File "C:\Users\kth00\Documents\GitHub\2024_2_GameEngineBase\Team4\Content\Dataprocess\predict.py", line 36, in predict_image
    raise RuntimeError(f"Prediction failed: {e}")
RuntimeError: Prediction failed: [Errno 13] Permission denied: 'C:/Users/kth00/Documents/GitHub/2024_2_GameEngineBase/Team4/Saved/SavedDrawing.png'
2024-12-13 18:04:17,446 [INFO] 127.0.0.1 - - [13/Dec/2024 18:04:17] "[35m[1mPOST /predict HTTP/1.1[0m" 500 -
2024-12-13 18:04:17,458 [DEBUG] Received request: {'file_path': 'C:/Users/kth00/Documents/GitHub/2024_2_GameEngineBase/Team4/Saved/'}
2024-12-13 18:04:17,459 [INFO] File path received: C:/Users/kth00/Documents/GitHub/2024_2_GameEngineBase/Team4/Saved/SavedDrawing.png
2024-12-13 18:04:17,460 [INFO] Starting prediction...
2024-12-13 18:04:17,478 [DEBUG] STREAM b'IHDR' 16 13
2024-12-13 18:04:17,479 [DEBUG] STREAM b'IDAT' 41 8192
2024-12-13 18:04:17,508 [INFO] Prediction result: K
2024-12-13 18:04:17,509 [INFO] 127.0.0.1 - - [13/Dec/2024 18:04:17] "POST /predict HTTP/1.1" 200 -
2024-12-13 18:04:17,557 [DEBUG] Received request: {'file_path': 'C:/Users/kth00/Documents/GitHub/2024_2_GameEngineBase/Team4/Saved/'}
2024-12-13 18:04:17,557 [INFO] File path received: C:/Users/kth00/Documents/GitHub/2024_2_GameEngineBase/Team4/Saved/SavedDrawing.png
2024-12-13 18:04:17,558 [INFO] Starting prediction...
2024-12-13 18:04:17,576 [ERROR] Error during prediction
Traceback (most recent call last):
  File "C:\Users\kth00\Documents\GitHub\2024_2_GameEngineBase\Team4\Content\Dataprocess\predict.py", line 23, in predict_image
    img = load_img(img_path, target_size=(224, 224))
  File "C:\Users\kth00\AppData\Local\Programs\Python\Python39\lib\site-packages\keras\utils\image_utils.py", line 422, in load_img
    with open(path, "rb") as f:
PermissionError: [Errno 13] Permission denied: 'C:/Users/kth00/Documents/GitHub/2024_2_GameEngineBase/Team4/Saved/SavedDrawing.png'

During handling of the above exception, another exception occurred:

Traceback (most recent call last):
  File "C:\Users\kth00\Documents\GitHub\2024_2_GameEngineBase\Team4\Content\Dataprocess\server.py", line 45, in predict
    prediction = predict_image(file_path)
  File "C:\Users\kth00\Documents\GitHub\2024_2_GameEngineBase\Team4\Content\Dataprocess\predict.py", line 36, in predict_image
    raise RuntimeError(f"Prediction failed: {e}")
RuntimeError: Prediction failed: [Errno 13] Permission denied: 'C:/Users/kth00/Documents/GitHub/2024_2_GameEngineBase/Team4/Saved/SavedDrawing.png'
2024-12-13 18:04:17,580 [INFO] 127.0.0.1 - - [13/Dec/2024 18:04:17] "[35m[1mPOST /predict HTTP/1.1[0m" 500 -
2024-12-13 18:04:17,594 [DEBUG] Received request: {'file_path': 'C:/Users/kth00/Documents/GitHub/2024_2_GameEngineBase/Team4/Saved/'}
2024-12-13 18:04:17,595 [INFO] File path received: C:/Users/kth00/Documents/GitHub/2024_2_GameEngineBase/Team4/Saved/SavedDrawing.png
2024-12-13 18:04:17,595 [INFO] Starting prediction...
2024-12-13 18:04:17,610 [DEBUG] STREAM b'IHDR' 16 13
2024-12-13 18:04:17,610 [DEBUG] STREAM b'IDAT' 41 8192
2024-12-13 18:04:17,642 [INFO] Prediction result: K
2024-12-13 18:04:17,643 [INFO] 127.0.0.1 - - [13/Dec/2024 18:04:17] "POST /predict HTTP/1.1" 200 -
2024-12-13 18:04:17,758 [DEBUG] Received request: {'file_path': 'C:/Users/kth00/Documents/GitHub/2024_2_GameEngineBase/Team4/Saved/'}
2024-12-13 18:04:17,758 [INFO] File path received: C:/Users/kth00/Documents/GitHub/2024_2_GameEngineBase/Team4/Saved/SavedDrawing.png
2024-12-13 18:04:17,759 [INFO] Starting prediction...
2024-12-13 18:04:17,772 [ERROR] Error during prediction
Traceback (most recent call last):
  File "C:\Users\kth00\Documents\GitHub\2024_2_GameEngineBase\Team4\Content\Dataprocess\predict.py", line 23, in predict_image
    img = load_img(img_path, target_size=(224, 224))
  File "C:\Users\kth00\AppData\Local\Programs\Python\Python39\lib\site-packages\keras\utils\image_utils.py", line 422, in load_img
    with open(path, "rb") as f:
PermissionError: [Errno 13] Permission denied: 'C:/Users/kth00/Documents/GitHub/2024_2_GameEngineBase/Team4/Saved/SavedDrawing.png'

During handling of the above exception, another exception occurred:

Traceback (most recent call last):
  File "C:\Users\kth00\Documents\GitHub\2024_2_GameEngineBase\Team4\Content\Dataprocess\server.py", line 45, in predict
    prediction = predict_image(file_path)
  File "C:\Users\kth00\Documents\GitHub\2024_2_GameEngineBase\Team4\Content\Dataprocess\predict.py", line 36, in predict_image
    raise RuntimeError(f"Prediction failed: {e}")
RuntimeError: Prediction failed: [Errno 13] Permission denied: 'C:/Users/kth00/Documents/GitHub/2024_2_GameEngineBase/Team4/Saved/SavedDrawing.png'
2024-12-13 18:04:17,775 [INFO] 127.0.0.1 - - [13/Dec/2024 18:04:17] "[35m[1mPOST /predict HTTP/1.1[0m" 500 -
2024-12-13 18:04:17,825 [DEBUG] Received request: {'file_path': 'C:/Users/kth00/Documents/GitHub/2024_2_GameEngineBase/Team4/Saved/'}
2024-12-13 18:04:17,825 [INFO] File path received: C:/Users/kth00/Documents/GitHub/2024_2_GameEngineBase/Team4/Saved/SavedDrawing.png
2024-12-13 18:04:17,826 [INFO] Starting prediction...
2024-12-13 18:04:17,840 [ERROR] Error during prediction
Traceback (most recent call last):
  File "C:\Users\kth00\Documents\GitHub\2024_2_GameEngineBase\Team4\Content\Dataprocess\predict.py", line 23, in predict_image
    img = load_img(img_path, target_size=(224, 224))
  File "C:\Users\kth00\AppData\Local\Programs\Python\Python39\lib\site-packages\keras\utils\image_utils.py", line 422, in load_img
    with open(path, "rb") as f:
PermissionError: [Errno 13] Permission denied: 'C:/Users/kth00/Documents/GitHub/2024_2_GameEngineBase/Team4/Saved/SavedDrawing.png'

During handling of the above exception, another exception occurred:

Traceback (most recent call last):
  File "C:\Users\kth00\Documents\GitHub\2024_2_GameEngineBase\Team4\Content\Dataprocess\server.py", line 45, in predict
    prediction = predict_image(file_path)
  File "C:\Users\kth00\Documents\GitHub\2024_2_GameEngineBase\Team4\Content\Dataprocess\predict.py", line 36, in predict_image
    raise RuntimeError(f"Prediction failed: {e}")
RuntimeError: Prediction failed: [Errno 13] Permission denied: 'C:/Users/kth00/Documents/GitHub/2024_2_GameEngineBase/Team4/Saved/SavedDrawing.png'
2024-12-13 18:04:17,843 [INFO] 127.0.0.1 - - [13/Dec/2024 18:04:17] "[35m[1mPOST /predict HTTP/1.1[0m" 500 -
2024-12-13 18:04:17,858 [DEBUG] Received request: {'file_path': 'C:/Users/kth00/Documents/GitHub/2024_2_GameEngineBase/Team4/Saved/'}
2024-12-13 18:04:17,858 [INFO] File path received: C:/Users/kth00/Documents/GitHub/2024_2_GameEngineBase/Team4/Saved/SavedDrawing.png
2024-12-13 18:04:17,858 [INFO] Starting prediction...
2024-12-13 18:04:17,877 [DEBUG] STREAM b'IHDR' 16 13
2024-12-13 18:04:17,878 [DEBUG] STREAM b'IDAT' 41 8192
2024-12-13 18:04:17,909 [INFO] Prediction result: K
2024-12-13 18:04:17,910 [INFO] 127.0.0.1 - - [13/Dec/2024 18:04:17] "POST /predict HTTP/1.1" 200 -
2024-12-13 18:04:17,993 [DEBUG] Received request: {'file_path': 'C:/Users/kth00/Documents/GitHub/2024_2_GameEngineBase/Team4/Saved/'}
2024-12-13 18:04:17,993 [INFO] File path received: C:/Users/kth00/Documents/GitHub/2024_2_GameEngineBase/Team4/Saved/SavedDrawing.png
2024-12-13 18:04:17,993 [INFO] Starting prediction...
2024-12-13 18:04:18,005 [ERROR] Error during prediction
Traceback (most recent call last):
  File "C:\Users\kth00\Documents\GitHub\2024_2_GameEngineBase\Team4\Content\Dataprocess\predict.py", line 23, in predict_image
    img = load_img(img_path, target_size=(224, 224))
  File "C:\Users\kth00\AppData\Local\Programs\Python\Python39\lib\site-packages\keras\utils\image_utils.py", line 422, in load_img
    with open(path, "rb") as f:
PermissionError: [Errno 13] Permission denied: 'C:/Users/kth00/Documents/GitHub/2024_2_GameEngineBase/Team4/Saved/SavedDrawing.png'

During handling of the above exception, another exception occurred:

Traceback (most recent call last):
  File "C:\Users\kth00\Documents\GitHub\2024_2_GameEngineBase\Team4\Content\Dataprocess\server.py", line 45, in predict
    prediction = predict_image(file_path)
  File "C:\Users\kth00\Documents\GitHub\2024_2_GameEngineBase\Team4\Content\Dataprocess\predict.py", line 36, in predict_image
    raise RuntimeError(f"Prediction failed: {e}")
RuntimeError: Prediction failed: [Errno 13] Permission denied: 'C:/Users/kth00/Documents/GitHub/2024_2_GameEngineBase/Team4/Saved/SavedDrawing.png'
2024-12-13 18:04:18,008 [INFO] 127.0.0.1 - - [13/Dec/2024 18:04:18] "[35m[1mPOST /predict HTTP/1.1[0m" 500 -
2024-12-13 18:04:18,022 [DEBUG] Received request: {'file_path': 'C:/Users/kth00/Documents/GitHub/2024_2_GameEngineBase/Team4/Saved/'}
2024-12-13 18:04:18,022 [INFO] File path received: C:/Users/kth00/Documents/GitHub/2024_2_GameEngineBase/Team4/Saved/SavedDrawing.png
2024-12-13 18:04:18,023 [INFO] Starting prediction...
2024-12-13 18:04:18,037 [ERROR] Error during prediction
Traceback (most recent call last):
  File "C:\Users\kth00\Documents\GitHub\2024_2_GameEngineBase\Team4\Content\Dataprocess\predict.py", line 23, in predict_image
    img = load_img(img_path, target_size=(224, 224))
  File "C:\Users\kth00\AppData\Local\Programs\Python\Python39\lib\site-packages\keras\utils\image_utils.py", line 422, in load_img
    with open(path, "rb") as f:
PermissionError: [Errno 13] Permission denied: 'C:/Users/kth00/Documents/GitHub/2024_2_GameEngineBase/Team4/Saved/SavedDrawing.png'

During handling of the above exception, another exception occurred:

Traceback (most recent call last):
  File "C:\Users\kth00\Documents\GitHub\2024_2_GameEngineBase\Team4\Content\Dataprocess\server.py", line 45, in predict
    prediction = predict_image(file_path)
  File "C:\Users\kth00\Documents\GitHub\2024_2_GameEngineBase\Team4\Content\Dataprocess\predict.py", line 36, in predict_image
    raise RuntimeError(f"Prediction failed: {e}")
RuntimeError: Prediction failed: [Errno 13] Permission denied: 'C:/Users/kth00/Documents/GitHub/2024_2_GameEngineBase/Team4/Saved/SavedDrawing.png'
2024-12-13 18:04:18,040 [INFO] 127.0.0.1 - - [13/Dec/2024 18:04:18] "[35m[1mPOST /predict HTTP/1.1[0m" 500 -
2024-12-13 18:04:18,087 [DEBUG] Received request: {'file_path': 'C:/Users/kth00/Documents/GitHub/2024_2_GameEngineBase/Team4/Saved/'}
2024-12-13 18:04:18,088 [INFO] File path received: C:/Users/kth00/Documents/GitHub/2024_2_GameEngineBase/Team4/Saved/SavedDrawing.png
2024-12-13 18:04:18,088 [INFO] Starting prediction...
2024-12-13 18:04:18,106 [DEBUG] STREAM b'IHDR' 16 13
2024-12-13 18:04:18,107 [DEBUG] STREAM b'IDAT' 41 8192
2024-12-13 18:04:18,119 [DEBUG] Received request: {'file_path': 'C:/Users/kth00/Documents/GitHub/2024_2_GameEngineBase/Team4/Saved/'}
2024-12-13 18:04:18,120 [INFO] File path received: C:/Users/kth00/Documents/GitHub/2024_2_GameEngineBase/Team4/Saved/SavedDrawing.png
2024-12-13 18:04:18,120 [INFO] Starting prediction...
2024-12-13 18:04:18,138 [ERROR] Error during prediction
Traceback (most recent call last):
  File "C:\Users\kth00\Documents\GitHub\2024_2_GameEngineBase\Team4\Content\Dataprocess\predict.py", line 23, in predict_image
    img = load_img(img_path, target_size=(224, 224))
  File "C:\Users\kth00\AppData\Local\Programs\Python\Python39\lib\site-packages\keras\utils\image_utils.py", line 422, in load_img
    with open(path, "rb") as f:
PermissionError: [Errno 13] Permission denied: 'C:/Users/kth00/Documents/GitHub/2024_2_GameEngineBase/Team4/Saved/SavedDrawing.png'

During handling of the above exception, another exception occurred:

Traceback (most recent call last):
  File "C:\Users\kth00\Documents\GitHub\2024_2_GameEngineBase\Team4\Content\Dataprocess\server.py", line 45, in predict
    prediction = predict_image(file_path)
  File "C:\Users\kth00\Documents\GitHub\2024_2_GameEngineBase\Team4\Content\Dataprocess\predict.py", line 36, in predict_image
    raise RuntimeError(f"Prediction failed: {e}")
RuntimeError: Prediction failed: [Errno 13] Permission denied: 'C:/Users/kth00/Documents/GitHub/2024_2_GameEngineBase/Team4/Saved/SavedDrawing.png'
2024-12-13 18:04:18,142 [INFO] 127.0.0.1 - - [13/Dec/2024 18:04:18] "[35m[1mPOST /predict HTTP/1.1[0m" 500 -
2024-12-13 18:04:18,145 [INFO] Prediction result: K
2024-12-13 18:04:18,146 [INFO] 127.0.0.1 - - [13/Dec/2024 18:04:18] "POST /predict HTTP/1.1" 200 -
2024-12-13 18:04:18,195 [DEBUG] Received request: {'file_path': 'C:/Users/kth00/Documents/GitHub/2024_2_GameEngineBase/Team4/Saved/'}
2024-12-13 18:04:18,196 [INFO] File path received: C:/Users/kth00/Documents/GitHub/2024_2_GameEngineBase/Team4/Saved/SavedDrawing.png
2024-12-13 18:04:18,196 [INFO] Starting prediction...
2024-12-13 18:04:18,213 [ERROR] Error during prediction
Traceback (most recent call last):
  File "C:\Users\kth00\Documents\GitHub\2024_2_GameEngineBase\Team4\Content\Dataprocess\predict.py", line 23, in predict_image
    img = load_img(img_path, target_size=(224, 224))
  File "C:\Users\kth00\AppData\Local\Programs\Python\Python39\lib\site-packages\keras\utils\image_utils.py", line 422, in load_img
    with open(path, "rb") as f:
PermissionError: [Errno 13] Permission denied: 'C:/Users/kth00/Documents/GitHub/2024_2_GameEngineBase/Team4/Saved/SavedDrawing.png'

During handling of the above exception, another exception occurred:

Traceback (most recent call last):
  File "C:\Users\kth00\Documents\GitHub\2024_2_GameEngineBase\Team4\Content\Dataprocess\server.py", line 45, in predict
    prediction = predict_image(file_path)
  File "C:\Users\kth00\Documents\GitHub\2024_2_GameEngineBase\Team4\Content\Dataprocess\predict.py", line 36, in predict_image
    raise RuntimeError(f"Prediction failed: {e}")
RuntimeError: Prediction failed: [Errno 13] Permission denied: 'C:/Users/kth00/Documents/GitHub/2024_2_GameEngineBase/Team4/Saved/SavedDrawing.png'
2024-12-13 18:04:18,215 [INFO] 127.0.0.1 - - [13/Dec/2024 18:04:18] "[35m[1mPOST /predict HTTP/1.1[0m" 500 -
2024-12-13 18:04:18,265 [DEBUG] Received request: {'file_path': 'C:/Users/kth00/Documents/GitHub/2024_2_GameEngineBase/Team4/Saved/'}
2024-12-13 18:04:18,265 [INFO] File path received: C:/Users/kth00/Documents/GitHub/2024_2_GameEngineBase/Team4/Saved/SavedDrawing.png
2024-12-13 18:04:18,265 [INFO] Starting prediction...
2024-12-13 18:04:18,284 [DEBUG] STREAM b'IHDR' 16 13
2024-12-13 18:04:18,284 [DEBUG] STREAM b'IDAT' 41 8192
2024-12-13 18:04:18,316 [INFO] Prediction result: K
2024-12-13 18:04:18,317 [INFO] 127.0.0.1 - - [13/Dec/2024 18:04:18] "POST /predict HTTP/1.1" 200 -
2024-12-13 18:04:18,395 [DEBUG] Received request: {'file_path': 'C:/Users/kth00/Documents/GitHub/2024_2_GameEngineBase/Team4/Saved/'}
2024-12-13 18:04:18,395 [INFO] File path received: C:/Users/kth00/Documents/GitHub/2024_2_GameEngineBase/Team4/Saved/SavedDrawing.png
2024-12-13 18:04:18,396 [INFO] Starting prediction...
2024-12-13 18:04:18,409 [ERROR] Error during prediction
Traceback (most recent call last):
  File "C:\Users\kth00\Documents\GitHub\2024_2_GameEngineBase\Team4\Content\Dataprocess\predict.py", line 23, in predict_image
    img = load_img(img_path, target_size=(224, 224))
  File "C:\Users\kth00\AppData\Local\Programs\Python\Python39\lib\site-packages\keras\utils\image_utils.py", line 422, in load_img
    with open(path, "rb") as f:
PermissionError: [Errno 13] Permission denied: 'C:/Users/kth00/Documents/GitHub/2024_2_GameEngineBase/Team4/Saved/SavedDrawing.png'

During handling of the above exception, another exception occurred:

Traceback (most recent call last):
  File "C:\Users\kth00\Documents\GitHub\2024_2_GameEngineBase\Team4\Content\Dataprocess\server.py", line 45, in predict
    prediction = predict_image(file_path)
  File "C:\Users\kth00\Documents\GitHub\2024_2_GameEngineBase\Team4\Content\Dataprocess\predict.py", line 36, in predict_image
    raise RuntimeError(f"Prediction failed: {e}")
RuntimeError: Prediction failed: [Errno 13] Permission denied: 'C:/Users/kth00/Documents/GitHub/2024_2_GameEngineBase/Team4/Saved/SavedDrawing.png'
2024-12-13 18:04:18,412 [INFO] 127.0.0.1 - - [13/Dec/2024 18:04:18] "[35m[1mPOST /predict HTTP/1.1[0m" 500 -
2024-12-13 18:04:18,428 [DEBUG] Received request: {'file_path': 'C:/Users/kth00/Documents/GitHub/2024_2_GameEngineBase/Team4/Saved/'}
2024-12-13 18:04:18,429 [INFO] File path received: C:/Users/kth00/Documents/GitHub/2024_2_GameEngineBase/Team4/Saved/SavedDrawing.png
2024-12-13 18:04:18,429 [INFO] Starting prediction...
2024-12-13 18:04:18,445 [ERROR] Error during prediction
Traceback (most recent call last):
  File "C:\Users\kth00\Documents\GitHub\2024_2_GameEngineBase\Team4\Content\Dataprocess\predict.py", line 23, in predict_image
    img = load_img(img_path, target_size=(224, 224))
  File "C:\Users\kth00\AppData\Local\Programs\Python\Python39\lib\site-packages\keras\utils\image_utils.py", line 422, in load_img
    with open(path, "rb") as f:
PermissionError: [Errno 13] Permission denied: 'C:/Users/kth00/Documents/GitHub/2024_2_GameEngineBase/Team4/Saved/SavedDrawing.png'

During handling of the above exception, another exception occurred:

Traceback (most recent call last):
  File "C:\Users\kth00\Documents\GitHub\2024_2_GameEngineBase\Team4\Content\Dataprocess\server.py", line 45, in predict
    prediction = predict_image(file_path)
  File "C:\Users\kth00\Documents\GitHub\2024_2_GameEngineBase\Team4\Content\Dataprocess\predict.py", line 36, in predict_image
    raise RuntimeError(f"Prediction failed: {e}")
RuntimeError: Prediction failed: [Errno 13] Permission denied: 'C:/Users/kth00/Documents/GitHub/2024_2_GameEngineBase/Team4/Saved/SavedDrawing.png'
2024-12-13 18:04:18,447 [INFO] 127.0.0.1 - - [13/Dec/2024 18:04:18] "[35m[1mPOST /predict HTTP/1.1[0m" 500 -
2024-12-13 18:04:18,497 [DEBUG] Received request: {'file_path': 'C:/Users/kth00/Documents/GitHub/2024_2_GameEngineBase/Team4/Saved/'}
2024-12-13 18:04:18,498 [INFO] File path received: C:/Users/kth00/Documents/GitHub/2024_2_GameEngineBase/Team4/Saved/SavedDrawing.png
2024-12-13 18:04:18,498 [INFO] Starting prediction...
2024-12-13 18:04:18,517 [DEBUG] STREAM b'IHDR' 16 13
2024-12-13 18:04:18,518 [DEBUG] STREAM b'IDAT' 41 8192
2024-12-13 18:04:18,548 [INFO] Prediction result: K
2024-12-13 18:04:18,549 [INFO] 127.0.0.1 - - [13/Dec/2024 18:04:18] "POST /predict HTTP/1.1" 200 -
2024-12-13 18:04:18,627 [DEBUG] Received request: {'file_path': 'C:/Users/kth00/Documents/GitHub/2024_2_GameEngineBase/Team4/Saved/'}
2024-12-13 18:04:18,628 [INFO] File path received: C:/Users/kth00/Documents/GitHub/2024_2_GameEngineBase/Team4/Saved/SavedDrawing.png
2024-12-13 18:04:18,628 [INFO] Starting prediction...
2024-12-13 18:04:18,645 [ERROR] Error during prediction
Traceback (most recent call last):
  File "C:\Users\kth00\Documents\GitHub\2024_2_GameEngineBase\Team4\Content\Dataprocess\predict.py", line 23, in predict_image
    img = load_img(img_path, target_size=(224, 224))
  File "C:\Users\kth00\AppData\Local\Programs\Python\Python39\lib\site-packages\keras\utils\image_utils.py", line 422, in load_img
    with open(path, "rb") as f:
PermissionError: [Errno 13] Permission denied: 'C:/Users/kth00/Documents/GitHub/2024_2_GameEngineBase/Team4/Saved/SavedDrawing.png'

During handling of the above exception, another exception occurred:

Traceback (most recent call last):
  File "C:\Users\kth00\Documents\GitHub\2024_2_GameEngineBase\Team4\Content\Dataprocess\server.py", line 45, in predict
    prediction = predict_image(file_path)
  File "C:\Users\kth00\Documents\GitHub\2024_2_GameEngineBase\Team4\Content\Dataprocess\predict.py", line 36, in predict_image
    raise RuntimeError(f"Prediction failed: {e}")
RuntimeError: Prediction failed: [Errno 13] Permission denied: 'C:/Users/kth00/Documents/GitHub/2024_2_GameEngineBase/Team4/Saved/SavedDrawing.png'
2024-12-13 18:04:18,649 [INFO] 127.0.0.1 - - [13/Dec/2024 18:04:18] "[35m[1mPOST /predict HTTP/1.1[0m" 500 -
2024-12-13 18:04:18,694 [DEBUG] Received request: {'file_path': 'C:/Users/kth00/Documents/GitHub/2024_2_GameEngineBase/Team4/Saved/'}
2024-12-13 18:04:18,695 [INFO] File path received: C:/Users/kth00/Documents/GitHub/2024_2_GameEngineBase/Team4/Saved/SavedDrawing.png
2024-12-13 18:04:18,695 [INFO] Starting prediction...
2024-12-13 18:04:18,710 [ERROR] Error during prediction
Traceback (most recent call last):
  File "C:\Users\kth00\Documents\GitHub\2024_2_GameEngineBase\Team4\Content\Dataprocess\predict.py", line 23, in predict_image
    img = load_img(img_path, target_size=(224, 224))
  File "C:\Users\kth00\AppData\Local\Programs\Python\Python39\lib\site-packages\keras\utils\image_utils.py", line 422, in load_img
    with open(path, "rb") as f:
PermissionError: [Errno 13] Permission denied: 'C:/Users/kth00/Documents/GitHub/2024_2_GameEngineBase/Team4/Saved/SavedDrawing.png'

During handling of the above exception, another exception occurred:

Traceback (most recent call last):
  File "C:\Users\kth00\Documents\GitHub\2024_2_GameEngineBase\Team4\Content\Dataprocess\server.py", line 45, in predict
    prediction = predict_image(file_path)
  File "C:\Users\kth00\Documents\GitHub\2024_2_GameEngineBase\Team4\Content\Dataprocess\predict.py", line 36, in predict_image
    raise RuntimeError(f"Prediction failed: {e}")
RuntimeError: Prediction failed: [Errno 13] Permission denied: 'C:/Users/kth00/Documents/GitHub/2024_2_GameEngineBase/Team4/Saved/SavedDrawing.png'
2024-12-13 18:04:18,713 [INFO] 127.0.0.1 - - [13/Dec/2024 18:04:18] "[35m[1mPOST /predict HTTP/1.1[0m" 500 -
2024-12-13 18:04:18,728 [DEBUG] Received request: {'file_path': 'C:/Users/kth00/Documents/GitHub/2024_2_GameEngineBase/Team4/Saved/'}
2024-12-13 18:04:18,729 [INFO] File path received: C:/Users/kth00/Documents/GitHub/2024_2_GameEngineBase/Team4/Saved/SavedDrawing.png
2024-12-13 18:04:18,729 [INFO] Starting prediction...
2024-12-13 18:04:18,746 [DEBUG] STREAM b'IHDR' 16 13
2024-12-13 18:04:18,746 [DEBUG] STREAM b'IDAT' 41 8192
2024-12-13 18:04:18,779 [INFO] Prediction result: K
2024-12-13 18:04:18,780 [INFO] 127.0.0.1 - - [13/Dec/2024 18:04:18] "POST /predict HTTP/1.1" 200 -
2024-12-13 18:04:18,895 [DEBUG] Received request: {'file_path': 'C:/Users/kth00/Documents/GitHub/2024_2_GameEngineBase/Team4/Saved/'}
2024-12-13 18:04:18,895 [INFO] File path received: C:/Users/kth00/Documents/GitHub/2024_2_GameEngineBase/Team4/Saved/SavedDrawing.png
2024-12-13 18:04:18,896 [INFO] Starting prediction...
2024-12-13 18:04:18,910 [ERROR] Error during prediction
Traceback (most recent call last):
  File "C:\Users\kth00\Documents\GitHub\2024_2_GameEngineBase\Team4\Content\Dataprocess\predict.py", line 23, in predict_image
    img = load_img(img_path, target_size=(224, 224))
  File "C:\Users\kth00\AppData\Local\Programs\Python\Python39\lib\site-packages\keras\utils\image_utils.py", line 422, in load_img
    with open(path, "rb") as f:
PermissionError: [Errno 13] Permission denied: 'C:/Users/kth00/Documents/GitHub/2024_2_GameEngineBase/Team4/Saved/SavedDrawing.png'

During handling of the above exception, another exception occurred:

Traceback (most recent call last):
  File "C:\Users\kth00\Documents\GitHub\2024_2_GameEngineBase\Team4\Content\Dataprocess\server.py", line 45, in predict
    prediction = predict_image(file_path)
  File "C:\Users\kth00\Documents\GitHub\2024_2_GameEngineBase\Team4\Content\Dataprocess\predict.py", line 36, in predict_image
    raise RuntimeError(f"Prediction failed: {e}")
RuntimeError: Prediction failed: [Errno 13] Permission denied: 'C:/Users/kth00/Documents/GitHub/2024_2_GameEngineBase/Team4/Saved/SavedDrawing.png'
2024-12-13 18:04:18,915 [INFO] 127.0.0.1 - - [13/Dec/2024 18:04:18] "[35m[1mPOST /predict HTTP/1.1[0m" 500 -
2024-12-13 18:04:18,964 [DEBUG] Received request: {'file_path': 'C:/Users/kth00/Documents/GitHub/2024_2_GameEngineBase/Team4/Saved/'}
2024-12-13 18:04:18,964 [INFO] File path received: C:/Users/kth00/Documents/GitHub/2024_2_GameEngineBase/Team4/Saved/SavedDrawing.png
2024-12-13 18:04:18,964 [INFO] Starting prediction...
2024-12-13 18:04:18,984 [DEBUG] STREAM b'IHDR' 16 13
2024-12-13 18:04:18,985 [DEBUG] STREAM b'IDAT' 41 8192
2024-12-13 18:04:19,018 [INFO] Prediction result: K
2024-12-13 18:04:19,019 [INFO] 127.0.0.1 - - [13/Dec/2024 18:04:19] "POST /predict HTTP/1.1" 200 -
2024-12-13 18:04:20,039 [DEBUG] Received request: {'file_path': 'C:/Users/kth00/Documents/GitHub/2024_2_GameEngineBase/Team4/Saved/'}
2024-12-13 18:04:20,040 [INFO] File path received: C:/Users/kth00/Documents/GitHub/2024_2_GameEngineBase/Team4/Saved/SavedDrawing.png
2024-12-13 18:04:20,041 [INFO] Starting prediction...
2024-12-13 18:04:20,057 [ERROR] Error during prediction
Traceback (most recent call last):
  File "C:\Users\kth00\Documents\GitHub\2024_2_GameEngineBase\Team4\Content\Dataprocess\predict.py", line 23, in predict_image
    img = load_img(img_path, target_size=(224, 224))
  File "C:\Users\kth00\AppData\Local\Programs\Python\Python39\lib\site-packages\keras\utils\image_utils.py", line 422, in load_img
    with open(path, "rb") as f:
PermissionError: [Errno 13] Permission denied: 'C:/Users/kth00/Documents/GitHub/2024_2_GameEngineBase/Team4/Saved/SavedDrawing.png'

During handling of the above exception, another exception occurred:

Traceback (most recent call last):
  File "C:\Users\kth00\Documents\GitHub\2024_2_GameEngineBase\Team4\Content\Dataprocess\server.py", line 45, in predict
    prediction = predict_image(file_path)
  File "C:\Users\kth00\Documents\GitHub\2024_2_GameEngineBase\Team4\Content\Dataprocess\predict.py", line 36, in predict_image
    raise RuntimeError(f"Prediction failed: {e}")
RuntimeError: Prediction failed: [Errno 13] Permission denied: 'C:/Users/kth00/Documents/GitHub/2024_2_GameEngineBase/Team4/Saved/SavedDrawing.png'
2024-12-13 18:04:20,060 [INFO] 127.0.0.1 - - [13/Dec/2024 18:04:20] "[35m[1mPOST /predict HTTP/1.1[0m" 500 -
2024-12-13 18:04:20,106 [DEBUG] Received request: {'file_path': 'C:/Users/kth00/Documents/GitHub/2024_2_GameEngineBase/Team4/Saved/'}
2024-12-13 18:04:20,106 [INFO] File path received: C:/Users/kth00/Documents/GitHub/2024_2_GameEngineBase/Team4/Saved/SavedDrawing.png
2024-12-13 18:04:20,106 [INFO] Starting prediction...
2024-12-13 18:04:20,124 [DEBUG] STREAM b'IHDR' 16 13
2024-12-13 18:04:20,125 [DEBUG] STREAM b'IDAT' 41 8192
2024-12-13 18:04:20,155 [INFO] Prediction result: K
2024-12-13 18:04:20,155 [INFO] 127.0.0.1 - - [13/Dec/2024 18:04:20] "POST /predict HTTP/1.1" 200 -
2024-12-13 18:06:16,853 [DEBUG] Received request: {'file_path': 'C:/Users/kth00/Documents/GitHub/2024_2_GameEngineBase/Team4/Saved/'}
2024-12-13 18:06:16,854 [INFO] File path received: C:/Users/kth00/Documents/GitHub/2024_2_GameEngineBase/Team4/Saved/SavedDrawing.png
2024-12-13 18:06:16,855 [INFO] Starting prediction...
2024-12-13 18:06:16,874 [DEBUG] STREAM b'IHDR' 16 13
2024-12-13 18:06:16,875 [DEBUG] STREAM b'IDAT' 41 8192
2024-12-13 18:06:16,909 [INFO] Prediction result: K
2024-12-13 18:06:16,909 [INFO] 127.0.0.1 - - [13/Dec/2024 18:06:16] "POST /predict HTTP/1.1" 200 -
2024-12-13 18:06:31,699 [DEBUG] Received request: {'file_path': 'C:/Users/kth00/Documents/GitHub/2024_2_GameEngineBase/Team4/Saved/'}
2024-12-13 18:06:31,699 [INFO] File path received: C:/Users/kth00/Documents/GitHub/2024_2_GameEngineBase/Team4/Saved/SavedDrawing.png
2024-12-13 18:06:31,699 [INFO] Starting prediction...
2024-12-13 18:06:31,716 [ERROR] Error during prediction
Traceback (most recent call last):
  File "C:\Users\kth00\Documents\GitHub\2024_2_GameEngineBase\Team4\Content\Dataprocess\predict.py", line 23, in predict_image
    img = load_img(img_path, target_size=(224, 224))
  File "C:\Users\kth00\AppData\Local\Programs\Python\Python39\lib\site-packages\keras\utils\image_utils.py", line 422, in load_img
    with open(path, "rb") as f:
PermissionError: [Errno 13] Permission denied: 'C:/Users/kth00/Documents/GitHub/2024_2_GameEngineBase/Team4/Saved/SavedDrawing.png'

During handling of the above exception, another exception occurred:

Traceback (most recent call last):
  File "C:\Users\kth00\Documents\GitHub\2024_2_GameEngineBase\Team4\Content\Dataprocess\server.py", line 45, in predict
    prediction = predict_image(file_path)
  File "C:\Users\kth00\Documents\GitHub\2024_2_GameEngineBase\Team4\Content\Dataprocess\predict.py", line 36, in predict_image
    raise RuntimeError(f"Prediction failed: {e}")
RuntimeError: Prediction failed: [Errno 13] Permission denied: 'C:/Users/kth00/Documents/GitHub/2024_2_GameEngineBase/Team4/Saved/SavedDrawing.png'
2024-12-13 18:06:31,719 [INFO] 127.0.0.1 - - [13/Dec/2024 18:06:31] "[35m[1mPOST /predict HTTP/1.1[0m" 500 -
2024-12-13 18:06:31,768 [DEBUG] Received request: {'file_path': 'C:/Users/kth00/Documents/GitHub/2024_2_GameEngineBase/Team4/Saved/'}
2024-12-13 18:06:31,769 [INFO] File path received: C:/Users/kth00/Documents/GitHub/2024_2_GameEngineBase/Team4/Saved/SavedDrawing.png
2024-12-13 18:06:31,769 [INFO] Starting prediction...
2024-12-13 18:06:31,785 [DEBUG] STREAM b'IHDR' 16 13
2024-12-13 18:06:31,787 [DEBUG] STREAM b'IDAT' 41 8192
2024-12-13 18:06:31,817 [INFO] Prediction result: K
2024-12-13 18:06:31,818 [INFO] 127.0.0.1 - - [13/Dec/2024 18:06:31] "POST /predict HTTP/1.1" 200 -
2024-12-13 18:06:37,326 [DEBUG] Received request: {'file_path': 'C:/Users/kth00/Documents/GitHub/2024_2_GameEngineBase/Team4/Saved/'}
2024-12-13 18:06:37,326 [INFO] File path received: C:/Users/kth00/Documents/GitHub/2024_2_GameEngineBase/Team4/Saved/SavedDrawing.png
2024-12-13 18:06:37,326 [INFO] Starting prediction...
2024-12-13 18:06:37,341 [ERROR] Error during prediction
Traceback (most recent call last):
  File "C:\Users\kth00\Documents\GitHub\2024_2_GameEngineBase\Team4\Content\Dataprocess\predict.py", line 23, in predict_image
    img = load_img(img_path, target_size=(224, 224))
  File "C:\Users\kth00\AppData\Local\Programs\Python\Python39\lib\site-packages\keras\utils\image_utils.py", line 422, in load_img
    with open(path, "rb") as f:
PermissionError: [Errno 13] Permission denied: 'C:/Users/kth00/Documents/GitHub/2024_2_GameEngineBase/Team4/Saved/SavedDrawing.png'

During handling of the above exception, another exception occurred:

Traceback (most recent call last):
  File "C:\Users\kth00\Documents\GitHub\2024_2_GameEngineBase\Team4\Content\Dataprocess\server.py", line 45, in predict
    prediction = predict_image(file_path)
  File "C:\Users\kth00\Documents\GitHub\2024_2_GameEngineBase\Team4\Content\Dataprocess\predict.py", line 36, in predict_image
    raise RuntimeError(f"Prediction failed: {e}")
RuntimeError: Prediction failed: [Errno 13] Permission denied: 'C:/Users/kth00/Documents/GitHub/2024_2_GameEngineBase/Team4/Saved/SavedDrawing.png'
2024-12-13 18:06:37,343 [INFO] 127.0.0.1 - - [13/Dec/2024 18:06:37] "[35m[1mPOST /predict HTTP/1.1[0m" 500 -
2024-12-13 18:06:37,393 [DEBUG] Received request: {'file_path': 'C:/Users/kth00/Documents/GitHub/2024_2_GameEngineBase/Team4/Saved/'}
2024-12-13 18:06:37,393 [INFO] File path received: C:/Users/kth00/Documents/GitHub/2024_2_GameEngineBase/Team4/Saved/SavedDrawing.png
2024-12-13 18:06:37,393 [INFO] Starting prediction...
2024-12-13 18:06:37,409 [ERROR] Error during prediction
Traceback (most recent call last):
  File "C:\Users\kth00\Documents\GitHub\2024_2_GameEngineBase\Team4\Content\Dataprocess\predict.py", line 23, in predict_image
    img = load_img(img_path, target_size=(224, 224))
  File "C:\Users\kth00\AppData\Local\Programs\Python\Python39\lib\site-packages\keras\utils\image_utils.py", line 422, in load_img
    with open(path, "rb") as f:
PermissionError: [Errno 13] Permission denied: 'C:/Users/kth00/Documents/GitHub/2024_2_GameEngineBase/Team4/Saved/SavedDrawing.png'

During handling of the above exception, another exception occurred:

Traceback (most recent call last):
  File "C:\Users\kth00\Documents\GitHub\2024_2_GameEngineBase\Team4\Content\Dataprocess\server.py", line 45, in predict
    prediction = predict_image(file_path)
  File "C:\Users\kth00\Documents\GitHub\2024_2_GameEngineBase\Team4\Content\Dataprocess\predict.py", line 36, in predict_image
    raise RuntimeError(f"Prediction failed: {e}")
RuntimeError: Prediction failed: [Errno 13] Permission denied: 'C:/Users/kth00/Documents/GitHub/2024_2_GameEngineBase/Team4/Saved/SavedDrawing.png'
2024-12-13 18:06:37,411 [INFO] 127.0.0.1 - - [13/Dec/2024 18:06:37] "[35m[1mPOST /predict HTTP/1.1[0m" 500 -
2024-12-13 18:06:37,461 [DEBUG] Received request: {'file_path': 'C:/Users/kth00/Documents/GitHub/2024_2_GameEngineBase/Team4/Saved/'}
2024-12-13 18:06:37,461 [INFO] File path received: C:/Users/kth00/Documents/GitHub/2024_2_GameEngineBase/Team4/Saved/SavedDrawing.png
2024-12-13 18:06:37,462 [INFO] Starting prediction...
2024-12-13 18:06:37,479 [DEBUG] STREAM b'IHDR' 16 13
2024-12-13 18:06:37,481 [DEBUG] STREAM b'IDAT' 41 8192
2024-12-13 18:06:37,514 [INFO] Prediction result: K
2024-12-13 18:06:37,515 [INFO] 127.0.0.1 - - [13/Dec/2024 18:06:37] "POST /predict HTTP/1.1" 200 -
2024-12-13 18:06:53,558 [DEBUG] Received request: {'file_path': 'C:/Users/kth00/Documents/GitHub/2024_2_GameEngineBase/Team4/Saved/'}
2024-12-13 18:06:53,559 [INFO] File path received: C:/Users/kth00/Documents/GitHub/2024_2_GameEngineBase/Team4/Saved/SavedDrawing.png
2024-12-13 18:06:53,559 [INFO] Starting prediction...
2024-12-13 18:06:53,577 [DEBUG] STREAM b'IHDR' 16 13
2024-12-13 18:06:53,577 [DEBUG] STREAM b'IDAT' 41 8192
2024-12-13 18:06:53,607 [INFO] Prediction result: K
2024-12-13 18:06:53,608 [INFO] 127.0.0.1 - - [13/Dec/2024 18:06:53] "POST /predict HTTP/1.1" 200 -
2024-12-13 18:10:15,671 [DEBUG] Received request: {'file_path': 'C:/Users/kth00/Documents/GitHub/2024_2_GameEngineBase/Team4/Saved/'}
2024-12-13 18:10:15,672 [INFO] File path received: C:/Users/kth00/Documents/GitHub/2024_2_GameEngineBase/Team4/Saved/SavedDrawing.png
2024-12-13 18:10:15,672 [INFO] Starting prediction...
2024-12-13 18:10:15,689 [DEBUG] STREAM b'IHDR' 16 13
2024-12-13 18:10:15,690 [DEBUG] STREAM b'IDAT' 41 8192
2024-12-13 18:10:15,723 [INFO] Prediction result: K
2024-12-13 18:10:15,724 [INFO] 127.0.0.1 - - [13/Dec/2024 18:10:15] "POST /predict HTTP/1.1" 200 -
2024-12-13 18:17:02,997 [DEBUG] Received request: {'file_path': 'C:/Users/kth00/Documents/GitHub/2024_2_GameEngineBase/Team4/Saved/'}
2024-12-13 18:17:02,998 [INFO] File path received: C:/Users/kth00/Documents/GitHub/2024_2_GameEngineBase/Team4/Saved/SavedDrawing.png
2024-12-13 18:17:02,998 [INFO] Starting prediction...
2024-12-13 18:17:03,012 [DEBUG] STREAM b'IHDR' 16 13
2024-12-13 18:17:03,014 [DEBUG] STREAM b'IDAT' 41 8192
2024-12-13 18:17:03,046 [INFO] Prediction result: K
2024-12-13 18:17:03,047 [INFO] 127.0.0.1 - - [13/Dec/2024 18:17:03] "POST /predict HTTP/1.1" 200 -
2024-12-13 18:17:16,584 [DEBUG] Received request: {'file_path': 'C:/Users/kth00/Documents/GitHub/2024_2_GameEngineBase/Team4/Saved/'}
2024-12-13 18:17:16,585 [INFO] File path received: C:/Users/kth00/Documents/GitHub/2024_2_GameEngineBase/Team4/Saved/SavedDrawing.png
2024-12-13 18:17:16,589 [INFO] Starting prediction...
2024-12-13 18:17:16,646 [DEBUG] STREAM b'IHDR' 16 13
2024-12-13 18:17:16,646 [DEBUG] STREAM b'IDAT' 41 8192
2024-12-13 18:17:16,682 [INFO] Prediction result: K
2024-12-13 18:17:16,683 [INFO] 127.0.0.1 - - [13/Dec/2024 18:17:16] "POST /predict HTTP/1.1" 200 -
2024-12-13 18:21:05,989 [DEBUG] Received request: {'file_path': 'C:/Users/kth00/Documents/GitHub/2024_2_GameEngineBase/Team4/Saved/'}
2024-12-13 18:21:05,989 [INFO] File path received: C:/Users/kth00/Documents/GitHub/2024_2_GameEngineBase/Team4/Saved/SavedDrawing.png
2024-12-13 18:21:05,989 [INFO] Starting prediction...
2024-12-13 18:21:06,008 [ERROR] Error during prediction
Traceback (most recent call last):
  File "C:\Users\kth00\Documents\GitHub\2024_2_GameEngineBase\Team4\Content\Dataprocess\predict.py", line 23, in predict_image
    img = load_img(img_path, target_size=(224, 224))
  File "C:\Users\kth00\AppData\Local\Programs\Python\Python39\lib\site-packages\keras\utils\image_utils.py", line 422, in load_img
    with open(path, "rb") as f:
PermissionError: [Errno 13] Permission denied: 'C:/Users/kth00/Documents/GitHub/2024_2_GameEngineBase/Team4/Saved/SavedDrawing.png'

During handling of the above exception, another exception occurred:

Traceback (most recent call last):
  File "C:\Users\kth00\Documents\GitHub\2024_2_GameEngineBase\Team4\Content\Dataprocess\server.py", line 45, in predict
    prediction = predict_image(file_path)
  File "C:\Users\kth00\Documents\GitHub\2024_2_GameEngineBase\Team4\Content\Dataprocess\predict.py", line 36, in predict_image
    raise RuntimeError(f"Prediction failed: {e}")
RuntimeError: Prediction failed: [Errno 13] Permission denied: 'C:/Users/kth00/Documents/GitHub/2024_2_GameEngineBase/Team4/Saved/SavedDrawing.png'
2024-12-13 18:21:06,010 [INFO] 127.0.0.1 - - [13/Dec/2024 18:21:06] "[35m[1mPOST /predict HTTP/1.1[0m" 500 -
2024-12-13 18:21:06,056 [DEBUG] Received request: {'file_path': 'C:/Users/kth00/Documents/GitHub/2024_2_GameEngineBase/Team4/Saved/'}
2024-12-13 18:21:06,057 [INFO] File path received: C:/Users/kth00/Documents/GitHub/2024_2_GameEngineBase/Team4/Saved/SavedDrawing.png
2024-12-13 18:21:06,057 [INFO] Starting prediction...
2024-12-13 18:21:06,072 [DEBUG] STREAM b'IHDR' 16 13
2024-12-13 18:21:06,072 [DEBUG] STREAM b'IDAT' 41 8192
2024-12-13 18:21:06,099 [INFO] Prediction result: T
2024-12-13 18:21:06,100 [INFO] 127.0.0.1 - - [13/Dec/2024 18:21:06] "POST /predict HTTP/1.1" 200 -
2024-12-13 18:22:53,933 [DEBUG] Received request: {'file_path': 'C:/Users/kth00/Documents/GitHub/2024_2_GameEngineBase/Team4/Saved/'}
2024-12-13 18:22:53,934 [INFO] File path received: C:/Users/kth00/Documents/GitHub/2024_2_GameEngineBase/Team4/Saved/SavedDrawing.png
2024-12-13 18:22:53,934 [INFO] Starting prediction...
2024-12-13 18:22:53,946 [ERROR] Error during prediction
Traceback (most recent call last):
  File "C:\Users\kth00\Documents\GitHub\2024_2_GameEngineBase\Team4\Content\Dataprocess\predict.py", line 23, in predict_image
    img = load_img(img_path, target_size=(224, 224))
  File "C:\Users\kth00\AppData\Local\Programs\Python\Python39\lib\site-packages\keras\utils\image_utils.py", line 422, in load_img
    with open(path, "rb") as f:
PermissionError: [Errno 13] Permission denied: 'C:/Users/kth00/Documents/GitHub/2024_2_GameEngineBase/Team4/Saved/SavedDrawing.png'

During handling of the above exception, another exception occurred:

Traceback (most recent call last):
  File "C:\Users\kth00\Documents\GitHub\2024_2_GameEngineBase\Team4\Content\Dataprocess\server.py", line 45, in predict
    prediction = predict_image(file_path)
  File "C:\Users\kth00\Documents\GitHub\2024_2_GameEngineBase\Team4\Content\Dataprocess\predict.py", line 36, in predict_image
    raise RuntimeError(f"Prediction failed: {e}")
RuntimeError: Prediction failed: [Errno 13] Permission denied: 'C:/Users/kth00/Documents/GitHub/2024_2_GameEngineBase/Team4/Saved/SavedDrawing.png'
2024-12-13 18:22:53,948 [INFO] 127.0.0.1 - - [13/Dec/2024 18:22:53] "[35m[1mPOST /predict HTTP/1.1[0m" 500 -
2024-12-13 18:22:54,001 [DEBUG] Received request: {'file_path': 'C:/Users/kth00/Documents/GitHub/2024_2_GameEngineBase/Team4/Saved/'}
2024-12-13 18:22:54,002 [INFO] File path received: C:/Users/kth00/Documents/GitHub/2024_2_GameEngineBase/Team4/Saved/SavedDrawing.png
2024-12-13 18:22:54,002 [INFO] Starting prediction...
2024-12-13 18:22:54,018 [DEBUG] STREAM b'IHDR' 16 13
2024-12-13 18:22:54,018 [DEBUG] STREAM b'IDAT' 41 8192
2024-12-13 18:22:54,046 [INFO] Prediction result: K
2024-12-13 18:22:54,047 [INFO] 127.0.0.1 - - [13/Dec/2024 18:22:54] "POST /predict HTTP/1.1" 200 -
2024-12-13 18:32:30,198 [DEBUG] Received request: {'file_path': 'C:/Users/kth00/Documents/GitHub/2024_2_GameEngineBase/Team4/Saved/'}
2024-12-13 18:32:30,199 [INFO] File path received: C:/Users/kth00/Documents/GitHub/2024_2_GameEngineBase/Team4/Saved/SavedDrawing.png
2024-12-13 18:32:30,199 [INFO] Starting prediction...
2024-12-13 18:32:30,213 [DEBUG] STREAM b'IHDR' 16 13
2024-12-13 18:32:30,214 [DEBUG] STREAM b'IDAT' 41 8192
2024-12-13 18:32:30,240 [INFO] Prediction result: K
2024-12-13 18:32:30,240 [INFO] 127.0.0.1 - - [13/Dec/2024 18:32:30] "POST /predict HTTP/1.1" 200 -
2024-12-13 18:33:09,709 [DEBUG] Received request: {'file_path': 'C:/Users/kth00/Documents/GitHub/2024_2_GameEngineBase/Team4/Saved/'}
2024-12-13 18:33:09,709 [INFO] File path received: C:/Users/kth00/Documents/GitHub/2024_2_GameEngineBase/Team4/Saved/SavedDrawing.png
2024-12-13 18:33:09,709 [INFO] Starting prediction...
2024-12-13 18:33:09,723 [DEBUG] STREAM b'IHDR' 16 13
2024-12-13 18:33:09,723 [DEBUG] STREAM b'IDAT' 41 8192
2024-12-13 18:33:09,753 [INFO] Prediction result: K
2024-12-13 18:33:09,753 [INFO] 127.0.0.1 - - [13/Dec/2024 18:33:09] "POST /predict HTTP/1.1" 200 -
2024-12-13 18:47:59,738 [DEBUG] Received request: {'file_path': 'C:/Users/kth00/Documents/GitHub/2024_2_GameEngineBase/Team4/Saved/'}
2024-12-13 18:47:59,739 [INFO] File path received: C:/Users/kth00/Documents/GitHub/2024_2_GameEngineBase/Team4/Saved/SavedDrawing.png
2024-12-13 18:47:59,739 [INFO] Starting prediction...
2024-12-13 18:47:59,752 [ERROR] Error during prediction
Traceback (most recent call last):
  File "C:\Users\kth00\Documents\GitHub\2024_2_GameEngineBase\Team4\Content\Dataprocess\predict.py", line 23, in predict_image
    img = load_img(img_path, target_size=(224, 224))
  File "C:\Users\kth00\AppData\Local\Programs\Python\Python39\lib\site-packages\keras\utils\image_utils.py", line 422, in load_img
    with open(path, "rb") as f:
PermissionError: [Errno 13] Permission denied: 'C:/Users/kth00/Documents/GitHub/2024_2_GameEngineBase/Team4/Saved/SavedDrawing.png'

During handling of the above exception, another exception occurred:

Traceback (most recent call last):
  File "C:\Users\kth00\Documents\GitHub\2024_2_GameEngineBase\Team4\Content\Dataprocess\server.py", line 45, in predict
    prediction = predict_image(file_path)
  File "C:\Users\kth00\Documents\GitHub\2024_2_GameEngineBase\Team4\Content\Dataprocess\predict.py", line 36, in predict_image
    raise RuntimeError(f"Prediction failed: {e}")
RuntimeError: Prediction failed: [Errno 13] Permission denied: 'C:/Users/kth00/Documents/GitHub/2024_2_GameEngineBase/Team4/Saved/SavedDrawing.png'
2024-12-13 18:47:59,755 [INFO] 127.0.0.1 - - [13/Dec/2024 18:47:59] "[35m[1mPOST /predict HTTP/1.1[0m" 500 -
2024-12-13 18:47:59,805 [DEBUG] Received request: {'file_path': 'C:/Users/kth00/Documents/GitHub/2024_2_GameEngineBase/Team4/Saved/'}
2024-12-13 18:47:59,805 [INFO] File path received: C:/Users/kth00/Documents/GitHub/2024_2_GameEngineBase/Team4/Saved/SavedDrawing.png
2024-12-13 18:47:59,806 [INFO] Starting prediction...
2024-12-13 18:47:59,824 [ERROR] Error during prediction
Traceback (most recent call last):
  File "C:\Users\kth00\Documents\GitHub\2024_2_GameEngineBase\Team4\Content\Dataprocess\predict.py", line 23, in predict_image
    img = load_img(img_path, target_size=(224, 224))
  File "C:\Users\kth00\AppData\Local\Programs\Python\Python39\lib\site-packages\keras\utils\image_utils.py", line 422, in load_img
    with open(path, "rb") as f:
PermissionError: [Errno 13] Permission denied: 'C:/Users/kth00/Documents/GitHub/2024_2_GameEngineBase/Team4/Saved/SavedDrawing.png'

During handling of the above exception, another exception occurred:

Traceback (most recent call last):
  File "C:\Users\kth00\Documents\GitHub\2024_2_GameEngineBase\Team4\Content\Dataprocess\server.py", line 45, in predict
    prediction = predict_image(file_path)
  File "C:\Users\kth00\Documents\GitHub\2024_2_GameEngineBase\Team4\Content\Dataprocess\predict.py", line 36, in predict_image
    raise RuntimeError(f"Prediction failed: {e}")
RuntimeError: Prediction failed: [Errno 13] Permission denied: 'C:/Users/kth00/Documents/GitHub/2024_2_GameEngineBase/Team4/Saved/SavedDrawing.png'
2024-12-13 18:47:59,828 [INFO] 127.0.0.1 - - [13/Dec/2024 18:47:59] "[35m[1mPOST /predict HTTP/1.1[0m" 500 -
2024-12-13 18:47:59,875 [DEBUG] Received request: {'file_path': 'C:/Users/kth00/Documents/GitHub/2024_2_GameEngineBase/Team4/Saved/'}
2024-12-13 18:47:59,875 [INFO] File path received: C:/Users/kth00/Documents/GitHub/2024_2_GameEngineBase/Team4/Saved/SavedDrawing.png
2024-12-13 18:47:59,875 [INFO] Starting prediction...
2024-12-13 18:47:59,895 [DEBUG] STREAM b'IHDR' 16 13
2024-12-13 18:47:59,895 [DEBUG] STREAM b'IDAT' 41 8192
2024-12-13 18:47:59,928 [INFO] Prediction result: K
2024-12-13 18:47:59,929 [INFO] 127.0.0.1 - - [13/Dec/2024 18:47:59] "POST /predict HTTP/1.1" 200 -
2024-12-13 18:48:29,152 [DEBUG] Received request: {'file_path': 'C:/Users/kth00/Documents/GitHub/2024_2_GameEngineBase/Team4/Saved/'}
2024-12-13 18:48:29,153 [INFO] File path received: C:/Users/kth00/Documents/GitHub/2024_2_GameEngineBase/Team4/Saved/SavedDrawing.png
2024-12-13 18:48:29,153 [INFO] Starting prediction...
2024-12-13 18:48:29,184 [DEBUG] STREAM b'IHDR' 16 13
2024-12-13 18:48:29,184 [DEBUG] STREAM b'IDAT' 41 8192
2024-12-13 18:48:29,220 [INFO] Prediction result: K
2024-12-13 18:48:29,222 [INFO] 127.0.0.1 - - [13/Dec/2024 18:48:29] "POST /predict HTTP/1.1" 200 -
2024-12-13 18:50:49,448 [DEBUG] Received request: {'file_path': 'C:/Users/kth00/Documents/GitHub/2024_2_GameEngineBase/Team4/Saved/'}
2024-12-13 18:50:49,449 [INFO] File path received: C:/Users/kth00/Documents/GitHub/2024_2_GameEngineBase/Team4/Saved/SavedDrawing.png
2024-12-13 18:50:49,449 [INFO] Starting prediction...
2024-12-13 18:50:49,484 [ERROR] Error during prediction
Traceback (most recent call last):
  File "C:\Users\kth00\Documents\GitHub\2024_2_GameEngineBase\Team4\Content\Dataprocess\predict.py", line 23, in predict_image
    img = load_img(img_path, target_size=(224, 224))
  File "C:\Users\kth00\AppData\Local\Programs\Python\Python39\lib\site-packages\keras\utils\image_utils.py", line 422, in load_img
    with open(path, "rb") as f:
PermissionError: [Errno 13] Permission denied: 'C:/Users/kth00/Documents/GitHub/2024_2_GameEngineBase/Team4/Saved/SavedDrawing.png'

During handling of the above exception, another exception occurred:

Traceback (most recent call last):
  File "C:\Users\kth00\Documents\GitHub\2024_2_GameEngineBase\Team4\Content\Dataprocess\server.py", line 45, in predict
    prediction = predict_image(file_path)
  File "C:\Users\kth00\Documents\GitHub\2024_2_GameEngineBase\Team4\Content\Dataprocess\predict.py", line 36, in predict_image
    raise RuntimeError(f"Prediction failed: {e}")
RuntimeError: Prediction failed: [Errno 13] Permission denied: 'C:/Users/kth00/Documents/GitHub/2024_2_GameEngineBase/Team4/Saved/SavedDrawing.png'
2024-12-13 18:50:49,488 [INFO] 127.0.0.1 - - [13/Dec/2024 18:50:49] "[35m[1mPOST /predict HTTP/1.1[0m" 500 -
2024-12-13 18:50:49,536 [DEBUG] Received request: {'file_path': 'C:/Users/kth00/Documents/GitHub/2024_2_GameEngineBase/Team4/Saved/'}
2024-12-13 18:50:49,537 [INFO] File path received: C:/Users/kth00/Documents/GitHub/2024_2_GameEngineBase/Team4/Saved/SavedDrawing.png
2024-12-13 18:50:49,537 [INFO] Starting prediction...
2024-12-13 18:50:49,556 [ERROR] Error during prediction
Traceback (most recent call last):
  File "C:\Users\kth00\Documents\GitHub\2024_2_GameEngineBase\Team4\Content\Dataprocess\predict.py", line 23, in predict_image
    img = load_img(img_path, target_size=(224, 224))
  File "C:\Users\kth00\AppData\Local\Programs\Python\Python39\lib\site-packages\keras\utils\image_utils.py", line 422, in load_img
    with open(path, "rb") as f:
PermissionError: [Errno 13] Permission denied: 'C:/Users/kth00/Documents/GitHub/2024_2_GameEngineBase/Team4/Saved/SavedDrawing.png'

During handling of the above exception, another exception occurred:

Traceback (most recent call last):
  File "C:\Users\kth00\Documents\GitHub\2024_2_GameEngineBase\Team4\Content\Dataprocess\server.py", line 45, in predict
    prediction = predict_image(file_path)
  File "C:\Users\kth00\Documents\GitHub\2024_2_GameEngineBase\Team4\Content\Dataprocess\predict.py", line 36, in predict_image
    raise RuntimeError(f"Prediction failed: {e}")
RuntimeError: Prediction failed: [Errno 13] Permission denied: 'C:/Users/kth00/Documents/GitHub/2024_2_GameEngineBase/Team4/Saved/SavedDrawing.png'
2024-12-13 18:50:49,559 [INFO] 127.0.0.1 - - [13/Dec/2024 18:50:49] "[35m[1mPOST /predict HTTP/1.1[0m" 500 -
2024-12-13 18:50:49,604 [DEBUG] Received request: {'file_path': 'C:/Users/kth00/Documents/GitHub/2024_2_GameEngineBase/Team4/Saved/'}
2024-12-13 18:50:49,605 [INFO] File path received: C:/Users/kth00/Documents/GitHub/2024_2_GameEngineBase/Team4/Saved/SavedDrawing.png
2024-12-13 18:50:49,605 [INFO] Starting prediction...
2024-12-13 18:50:49,626 [DEBUG] STREAM b'IHDR' 16 13
2024-12-13 18:50:49,626 [DEBUG] STREAM b'IDAT' 41 8192
2024-12-13 18:50:49,669 [INFO] Prediction result: T
2024-12-13 18:50:49,670 [INFO] 127.0.0.1 - - [13/Dec/2024 18:50:49] "POST /predict HTTP/1.1" 200 -
2024-12-13 18:52:43,050 [DEBUG] Received request: {'file_path': 'C:/Users/kth00/Documents/GitHub/2024_2_GameEngineBase/Team4/Saved/'}
2024-12-13 18:52:43,050 [INFO] File path received: C:/Users/kth00/Documents/GitHub/2024_2_GameEngineBase/Team4/Saved/SavedDrawing.png
2024-12-13 18:52:43,051 [INFO] Starting prediction...
2024-12-13 18:52:43,063 [ERROR] Error during prediction
Traceback (most recent call last):
  File "C:\Users\kth00\Documents\GitHub\2024_2_GameEngineBase\Team4\Content\Dataprocess\predict.py", line 23, in predict_image
    img = load_img(img_path, target_size=(224, 224))
  File "C:\Users\kth00\AppData\Local\Programs\Python\Python39\lib\site-packages\keras\utils\image_utils.py", line 422, in load_img
    with open(path, "rb") as f:
PermissionError: [Errno 13] Permission denied: 'C:/Users/kth00/Documents/GitHub/2024_2_GameEngineBase/Team4/Saved/SavedDrawing.png'

During handling of the above exception, another exception occurred:

Traceback (most recent call last):
  File "C:\Users\kth00\Documents\GitHub\2024_2_GameEngineBase\Team4\Content\Dataprocess\server.py", line 45, in predict
    prediction = predict_image(file_path)
  File "C:\Users\kth00\Documents\GitHub\2024_2_GameEngineBase\Team4\Content\Dataprocess\predict.py", line 36, in predict_image
    raise RuntimeError(f"Prediction failed: {e}")
RuntimeError: Prediction failed: [Errno 13] Permission denied: 'C:/Users/kth00/Documents/GitHub/2024_2_GameEngineBase/Team4/Saved/SavedDrawing.png'
2024-12-13 18:52:43,065 [INFO] 127.0.0.1 - - [13/Dec/2024 18:52:43] "[35m[1mPOST /predict HTTP/1.1[0m" 500 -
2024-12-13 18:52:43,116 [DEBUG] Received request: {'file_path': 'C:/Users/kth00/Documents/GitHub/2024_2_GameEngineBase/Team4/Saved/'}
2024-12-13 18:52:43,116 [INFO] File path received: C:/Users/kth00/Documents/GitHub/2024_2_GameEngineBase/Team4/Saved/SavedDrawing.png
2024-12-13 18:52:43,116 [INFO] Starting prediction...
2024-12-13 18:52:43,130 [DEBUG] STREAM b'IHDR' 16 13
2024-12-13 18:52:43,130 [DEBUG] STREAM b'IDAT' 41 8192
2024-12-13 18:52:43,157 [INFO] Prediction result: T
2024-12-13 18:52:43,163 [INFO] 127.0.0.1 - - [13/Dec/2024 18:52:43] "POST /predict HTTP/1.1" 200 -
2024-12-13 18:52:47,874 [DEBUG] Received request: {'file_path': 'C:/Users/kth00/Documents/GitHub/2024_2_GameEngineBase/Team4/Saved/'}
2024-12-13 18:52:47,874 [INFO] File path received: C:/Users/kth00/Documents/GitHub/2024_2_GameEngineBase/Team4/Saved/SavedDrawing.png
2024-12-13 18:52:47,874 [INFO] Starting prediction...
2024-12-13 18:52:47,889 [ERROR] Error during prediction
Traceback (most recent call last):
  File "C:\Users\kth00\Documents\GitHub\2024_2_GameEngineBase\Team4\Content\Dataprocess\predict.py", line 23, in predict_image
    img = load_img(img_path, target_size=(224, 224))
  File "C:\Users\kth00\AppData\Local\Programs\Python\Python39\lib\site-packages\keras\utils\image_utils.py", line 422, in load_img
    with open(path, "rb") as f:
PermissionError: [Errno 13] Permission denied: 'C:/Users/kth00/Documents/GitHub/2024_2_GameEngineBase/Team4/Saved/SavedDrawing.png'

During handling of the above exception, another exception occurred:

Traceback (most recent call last):
  File "C:\Users\kth00\Documents\GitHub\2024_2_GameEngineBase\Team4\Content\Dataprocess\server.py", line 45, in predict
    prediction = predict_image(file_path)
  File "C:\Users\kth00\Documents\GitHub\2024_2_GameEngineBase\Team4\Content\Dataprocess\predict.py", line 36, in predict_image
    raise RuntimeError(f"Prediction failed: {e}")
RuntimeError: Prediction failed: [Errno 13] Permission denied: 'C:/Users/kth00/Documents/GitHub/2024_2_GameEngineBase/Team4/Saved/SavedDrawing.png'
2024-12-13 18:52:47,891 [INFO] 127.0.0.1 - - [13/Dec/2024 18:52:47] "[35m[1mPOST /predict HTTP/1.1[0m" 500 -
2024-12-13 18:52:47,940 [DEBUG] Received request: {'file_path': 'C:/Users/kth00/Documents/GitHub/2024_2_GameEngineBase/Team4/Saved/'}
2024-12-13 18:52:47,941 [INFO] File path received: C:/Users/kth00/Documents/GitHub/2024_2_GameEngineBase/Team4/Saved/SavedDrawing.png
2024-12-13 18:52:47,941 [INFO] Starting prediction...
2024-12-13 18:52:47,960 [DEBUG] STREAM b'IHDR' 16 13
2024-12-13 18:52:47,961 [DEBUG] STREAM b'IDAT' 41 8192
2024-12-13 18:52:47,993 [INFO] Prediction result: K
2024-12-13 18:52:47,994 [INFO] 127.0.0.1 - - [13/Dec/2024 18:52:47] "POST /predict HTTP/1.1" 200 -
2024-12-13 18:54:13,648 [DEBUG] Received request: {'file_path': 'C:/Users/kth00/Documents/GitHub/2024_2_GameEngineBase/Team4/Saved/'}
2024-12-13 18:54:13,649 [INFO] File path received: C:/Users/kth00/Documents/GitHub/2024_2_GameEngineBase/Team4/Saved/SavedDrawing.png
2024-12-13 18:54:13,649 [INFO] Starting prediction...
2024-12-13 18:54:13,662 [ERROR] Error during prediction
Traceback (most recent call last):
  File "C:\Users\kth00\Documents\GitHub\2024_2_GameEngineBase\Team4\Content\Dataprocess\predict.py", line 23, in predict_image
    img = load_img(img_path, target_size=(224, 224))
  File "C:\Users\kth00\AppData\Local\Programs\Python\Python39\lib\site-packages\keras\utils\image_utils.py", line 422, in load_img
    with open(path, "rb") as f:
PermissionError: [Errno 13] Permission denied: 'C:/Users/kth00/Documents/GitHub/2024_2_GameEngineBase/Team4/Saved/SavedDrawing.png'

During handling of the above exception, another exception occurred:

Traceback (most recent call last):
  File "C:\Users\kth00\Documents\GitHub\2024_2_GameEngineBase\Team4\Content\Dataprocess\server.py", line 45, in predict
    prediction = predict_image(file_path)
  File "C:\Users\kth00\Documents\GitHub\2024_2_GameEngineBase\Team4\Content\Dataprocess\predict.py", line 36, in predict_image
    raise RuntimeError(f"Prediction failed: {e}")
RuntimeError: Prediction failed: [Errno 13] Permission denied: 'C:/Users/kth00/Documents/GitHub/2024_2_GameEngineBase/Team4/Saved/SavedDrawing.png'
2024-12-13 18:54:13,664 [INFO] 127.0.0.1 - - [13/Dec/2024 18:54:13] "[35m[1mPOST /predict HTTP/1.1[0m" 500 -
2024-12-13 18:54:13,714 [DEBUG] Received request: {'file_path': 'C:/Users/kth00/Documents/GitHub/2024_2_GameEngineBase/Team4/Saved/'}
2024-12-13 18:54:13,715 [INFO] File path received: C:/Users/kth00/Documents/GitHub/2024_2_GameEngineBase/Team4/Saved/SavedDrawing.png
2024-12-13 18:54:13,715 [INFO] Starting prediction...
2024-12-13 18:54:13,731 [DEBUG] STREAM b'IHDR' 16 13
2024-12-13 18:54:13,732 [DEBUG] STREAM b'IDAT' 41 8192
2024-12-13 18:54:13,764 [INFO] Prediction result: K
2024-12-13 18:54:13,764 [INFO] 127.0.0.1 - - [13/Dec/2024 18:54:13] "POST /predict HTTP/1.1" 200 -
2024-12-13 18:55:16,799 [DEBUG] Received request: {'file_path': 'C:/Users/kth00/Documents/GitHub/2024_2_GameEngineBase/Team4/Saved/'}
2024-12-13 18:55:16,800 [INFO] File path received: C:/Users/kth00/Documents/GitHub/2024_2_GameEngineBase/Team4/Saved/SavedDrawing.png
2024-12-13 18:55:16,800 [INFO] Starting prediction...
2024-12-13 18:55:16,815 [ERROR] Error during prediction
Traceback (most recent call last):
  File "C:\Users\kth00\Documents\GitHub\2024_2_GameEngineBase\Team4\Content\Dataprocess\predict.py", line 23, in predict_image
    img = load_img(img_path, target_size=(224, 224))
  File "C:\Users\kth00\AppData\Local\Programs\Python\Python39\lib\site-packages\keras\utils\image_utils.py", line 422, in load_img
    with open(path, "rb") as f:
PermissionError: [Errno 13] Permission denied: 'C:/Users/kth00/Documents/GitHub/2024_2_GameEngineBase/Team4/Saved/SavedDrawing.png'

During handling of the above exception, another exception occurred:

Traceback (most recent call last):
  File "C:\Users\kth00\Documents\GitHub\2024_2_GameEngineBase\Team4\Content\Dataprocess\server.py", line 45, in predict
    prediction = predict_image(file_path)
  File "C:\Users\kth00\Documents\GitHub\2024_2_GameEngineBase\Team4\Content\Dataprocess\predict.py", line 36, in predict_image
    raise RuntimeError(f"Prediction failed: {e}")
RuntimeError: Prediction failed: [Errno 13] Permission denied: 'C:/Users/kth00/Documents/GitHub/2024_2_GameEngineBase/Team4/Saved/SavedDrawing.png'
2024-12-13 18:55:16,817 [INFO] 127.0.0.1 - - [13/Dec/2024 18:55:16] "[35m[1mPOST /predict HTTP/1.1[0m" 500 -
2024-12-13 18:55:16,865 [DEBUG] Received request: {'file_path': 'C:/Users/kth00/Documents/GitHub/2024_2_GameEngineBase/Team4/Saved/'}
2024-12-13 18:55:16,866 [INFO] File path received: C:/Users/kth00/Documents/GitHub/2024_2_GameEngineBase/Team4/Saved/SavedDrawing.png
2024-12-13 18:55:16,866 [INFO] Starting prediction...
2024-12-13 18:55:16,879 [DEBUG] STREAM b'IHDR' 16 13
2024-12-13 18:55:16,879 [DEBUG] STREAM b'IDAT' 41 8192
2024-12-13 18:55:16,906 [INFO] Prediction result: K
2024-12-13 18:55:16,906 [INFO] 127.0.0.1 - - [13/Dec/2024 18:55:16] "POST /predict HTTP/1.1" 200 -
2024-12-13 18:55:23,923 [DEBUG] Received request: {'file_path': 'C:/Users/kth00/Documents/GitHub/2024_2_GameEngineBase/Team4/Saved/'}
2024-12-13 18:55:23,923 [INFO] File path received: C:/Users/kth00/Documents/GitHub/2024_2_GameEngineBase/Team4/Saved/SavedDrawing.png
2024-12-13 18:55:23,923 [INFO] Starting prediction...
2024-12-13 18:55:23,936 [ERROR] Error during prediction
Traceback (most recent call last):
  File "C:\Users\kth00\Documents\GitHub\2024_2_GameEngineBase\Team4\Content\Dataprocess\predict.py", line 23, in predict_image
    img = load_img(img_path, target_size=(224, 224))
  File "C:\Users\kth00\AppData\Local\Programs\Python\Python39\lib\site-packages\keras\utils\image_utils.py", line 422, in load_img
    with open(path, "rb") as f:
PermissionError: [Errno 13] Permission denied: 'C:/Users/kth00/Documents/GitHub/2024_2_GameEngineBase/Team4/Saved/SavedDrawing.png'

During handling of the above exception, another exception occurred:

Traceback (most recent call last):
  File "C:\Users\kth00\Documents\GitHub\2024_2_GameEngineBase\Team4\Content\Dataprocess\server.py", line 45, in predict
    prediction = predict_image(file_path)
  File "C:\Users\kth00\Documents\GitHub\2024_2_GameEngineBase\Team4\Content\Dataprocess\predict.py", line 36, in predict_image
    raise RuntimeError(f"Prediction failed: {e}")
RuntimeError: Prediction failed: [Errno 13] Permission denied: 'C:/Users/kth00/Documents/GitHub/2024_2_GameEngineBase/Team4/Saved/SavedDrawing.png'
2024-12-13 18:55:23,938 [INFO] 127.0.0.1 - - [13/Dec/2024 18:55:23] "[35m[1mPOST /predict HTTP/1.1[0m" 500 -
2024-12-13 18:55:23,951 [DEBUG] Received request: {'file_path': 'C:/Users/kth00/Documents/GitHub/2024_2_GameEngineBase/Team4/Saved/'}
2024-12-13 18:55:23,952 [INFO] File path received: C:/Users/kth00/Documents/GitHub/2024_2_GameEngineBase/Team4/Saved/SavedDrawing.png
2024-12-13 18:55:23,952 [INFO] Starting prediction...
2024-12-13 18:55:23,964 [ERROR] Error during prediction
Traceback (most recent call last):
  File "C:\Users\kth00\Documents\GitHub\2024_2_GameEngineBase\Team4\Content\Dataprocess\predict.py", line 23, in predict_image
    img = load_img(img_path, target_size=(224, 224))
  File "C:\Users\kth00\AppData\Local\Programs\Python\Python39\lib\site-packages\keras\utils\image_utils.py", line 422, in load_img
    with open(path, "rb") as f:
PermissionError: [Errno 13] Permission denied: 'C:/Users/kth00/Documents/GitHub/2024_2_GameEngineBase/Team4/Saved/SavedDrawing.png'

During handling of the above exception, another exception occurred:

Traceback (most recent call last):
  File "C:\Users\kth00\Documents\GitHub\2024_2_GameEngineBase\Team4\Content\Dataprocess\server.py", line 45, in predict
    prediction = predict_image(file_path)
  File "C:\Users\kth00\Documents\GitHub\2024_2_GameEngineBase\Team4\Content\Dataprocess\predict.py", line 36, in predict_image
    raise RuntimeError(f"Prediction failed: {e}")
RuntimeError: Prediction failed: [Errno 13] Permission denied: 'C:/Users/kth00/Documents/GitHub/2024_2_GameEngineBase/Team4/Saved/SavedDrawing.png'
2024-12-13 18:55:23,966 [INFO] 127.0.0.1 - - [13/Dec/2024 18:55:23] "[35m[1mPOST /predict HTTP/1.1[0m" 500 -
2024-12-13 18:55:24,014 [DEBUG] Received request: {'file_path': 'C:/Users/kth00/Documents/GitHub/2024_2_GameEngineBase/Team4/Saved/'}
2024-12-13 18:55:24,014 [INFO] File path received: C:/Users/kth00/Documents/GitHub/2024_2_GameEngineBase/Team4/Saved/SavedDrawing.png
2024-12-13 18:55:24,015 [INFO] Starting prediction...
2024-12-13 18:55:24,028 [DEBUG] STREAM b'IHDR' 16 13
2024-12-13 18:55:24,029 [DEBUG] STREAM b'IDAT' 41 8192
2024-12-13 18:55:24,054 [INFO] Prediction result: K
2024-12-13 18:55:24,055 [INFO] 127.0.0.1 - - [13/Dec/2024 18:55:24] "POST /predict HTTP/1.1" 200 -
2024-12-13 18:55:27,819 [DEBUG] Received request: {'file_path': 'C:/Users/kth00/Documents/GitHub/2024_2_GameEngineBase/Team4/Saved/'}
2024-12-13 18:55:27,820 [INFO] File path received: C:/Users/kth00/Documents/GitHub/2024_2_GameEngineBase/Team4/Saved/SavedDrawing.png
2024-12-13 18:55:27,820 [INFO] Starting prediction...
2024-12-13 18:55:27,831 [ERROR] Error during prediction
Traceback (most recent call last):
  File "C:\Users\kth00\Documents\GitHub\2024_2_GameEngineBase\Team4\Content\Dataprocess\predict.py", line 23, in predict_image
    img = load_img(img_path, target_size=(224, 224))
  File "C:\Users\kth00\AppData\Local\Programs\Python\Python39\lib\site-packages\keras\utils\image_utils.py", line 422, in load_img
    with open(path, "rb") as f:
PermissionError: [Errno 13] Permission denied: 'C:/Users/kth00/Documents/GitHub/2024_2_GameEngineBase/Team4/Saved/SavedDrawing.png'

During handling of the above exception, another exception occurred:

Traceback (most recent call last):
  File "C:\Users\kth00\Documents\GitHub\2024_2_GameEngineBase\Team4\Content\Dataprocess\server.py", line 45, in predict
    prediction = predict_image(file_path)
  File "C:\Users\kth00\Documents\GitHub\2024_2_GameEngineBase\Team4\Content\Dataprocess\predict.py", line 36, in predict_image
    raise RuntimeError(f"Prediction failed: {e}")
RuntimeError: Prediction failed: [Errno 13] Permission denied: 'C:/Users/kth00/Documents/GitHub/2024_2_GameEngineBase/Team4/Saved/SavedDrawing.png'
2024-12-13 18:55:27,834 [INFO] 127.0.0.1 - - [13/Dec/2024 18:55:27] "[35m[1mPOST /predict HTTP/1.1[0m" 500 -
2024-12-13 18:55:27,852 [DEBUG] Received request: {'file_path': 'C:/Users/kth00/Documents/GitHub/2024_2_GameEngineBase/Team4/Saved/'}
2024-12-13 18:55:27,853 [INFO] File path received: C:/Users/kth00/Documents/GitHub/2024_2_GameEngineBase/Team4/Saved/SavedDrawing.png
2024-12-13 18:55:27,853 [INFO] Starting prediction...
2024-12-13 18:55:27,867 [ERROR] Error during prediction
Traceback (most recent call last):
  File "C:\Users\kth00\Documents\GitHub\2024_2_GameEngineBase\Team4\Content\Dataprocess\predict.py", line 23, in predict_image
    img = load_img(img_path, target_size=(224, 224))
  File "C:\Users\kth00\AppData\Local\Programs\Python\Python39\lib\site-packages\keras\utils\image_utils.py", line 422, in load_img
    with open(path, "rb") as f:
PermissionError: [Errno 13] Permission denied: 'C:/Users/kth00/Documents/GitHub/2024_2_GameEngineBase/Team4/Saved/SavedDrawing.png'

During handling of the above exception, another exception occurred:

Traceback (most recent call last):
  File "C:\Users\kth00\Documents\GitHub\2024_2_GameEngineBase\Team4\Content\Dataprocess\server.py", line 45, in predict
    prediction = predict_image(file_path)
  File "C:\Users\kth00\Documents\GitHub\2024_2_GameEngineBase\Team4\Content\Dataprocess\predict.py", line 36, in predict_image
    raise RuntimeError(f"Prediction failed: {e}")
RuntimeError: Prediction failed: [Errno 13] Permission denied: 'C:/Users/kth00/Documents/GitHub/2024_2_GameEngineBase/Team4/Saved/SavedDrawing.png'
2024-12-13 18:55:27,869 [INFO] 127.0.0.1 - - [13/Dec/2024 18:55:27] "[35m[1mPOST /predict HTTP/1.1[0m" 500 -
2024-12-13 18:55:27,918 [DEBUG] Received request: {'file_path': 'C:/Users/kth00/Documents/GitHub/2024_2_GameEngineBase/Team4/Saved/'}
2024-12-13 18:55:27,919 [INFO] File path received: C:/Users/kth00/Documents/GitHub/2024_2_GameEngineBase/Team4/Saved/SavedDrawing.png
2024-12-13 18:55:27,919 [INFO] Starting prediction...
2024-12-13 18:55:27,934 [DEBUG] STREAM b'IHDR' 16 13
2024-12-13 18:55:27,934 [DEBUG] STREAM b'IDAT' 41 8192
2024-12-13 18:55:27,963 [INFO] Prediction result: T
2024-12-13 18:55:27,964 [INFO] 127.0.0.1 - - [13/Dec/2024 18:55:27] "POST /predict HTTP/1.1" 200 -
2024-12-13 18:55:31,331 [DEBUG] Received request: {'file_path': 'C:/Users/kth00/Documents/GitHub/2024_2_GameEngineBase/Team4/Saved/'}
2024-12-13 18:55:31,332 [INFO] File path received: C:/Users/kth00/Documents/GitHub/2024_2_GameEngineBase/Team4/Saved/SavedDrawing.png
2024-12-13 18:55:31,332 [INFO] Starting prediction...
2024-12-13 18:55:31,343 [ERROR] Error during prediction
Traceback (most recent call last):
  File "C:\Users\kth00\Documents\GitHub\2024_2_GameEngineBase\Team4\Content\Dataprocess\predict.py", line 23, in predict_image
    img = load_img(img_path, target_size=(224, 224))
  File "C:\Users\kth00\AppData\Local\Programs\Python\Python39\lib\site-packages\keras\utils\image_utils.py", line 422, in load_img
    with open(path, "rb") as f:
PermissionError: [Errno 13] Permission denied: 'C:/Users/kth00/Documents/GitHub/2024_2_GameEngineBase/Team4/Saved/SavedDrawing.png'

During handling of the above exception, another exception occurred:

Traceback (most recent call last):
  File "C:\Users\kth00\Documents\GitHub\2024_2_GameEngineBase\Team4\Content\Dataprocess\server.py", line 45, in predict
    prediction = predict_image(file_path)
  File "C:\Users\kth00\Documents\GitHub\2024_2_GameEngineBase\Team4\Content\Dataprocess\predict.py", line 36, in predict_image
    raise RuntimeError(f"Prediction failed: {e}")
RuntimeError: Prediction failed: [Errno 13] Permission denied: 'C:/Users/kth00/Documents/GitHub/2024_2_GameEngineBase/Team4/Saved/SavedDrawing.png'
2024-12-13 18:55:31,345 [INFO] 127.0.0.1 - - [13/Dec/2024 18:55:31] "[35m[1mPOST /predict HTTP/1.1[0m" 500 -
2024-12-13 18:55:31,363 [DEBUG] Received request: {'file_path': 'C:/Users/kth00/Documents/GitHub/2024_2_GameEngineBase/Team4/Saved/'}
2024-12-13 18:55:31,364 [INFO] File path received: C:/Users/kth00/Documents/GitHub/2024_2_GameEngineBase/Team4/Saved/SavedDrawing.png
2024-12-13 18:55:31,364 [INFO] Starting prediction...
2024-12-13 18:55:31,378 [ERROR] Error during prediction
Traceback (most recent call last):
  File "C:\Users\kth00\Documents\GitHub\2024_2_GameEngineBase\Team4\Content\Dataprocess\predict.py", line 23, in predict_image
    img = load_img(img_path, target_size=(224, 224))
  File "C:\Users\kth00\AppData\Local\Programs\Python\Python39\lib\site-packages\keras\utils\image_utils.py", line 422, in load_img
    with open(path, "rb") as f:
PermissionError: [Errno 13] Permission denied: 'C:/Users/kth00/Documents/GitHub/2024_2_GameEngineBase/Team4/Saved/SavedDrawing.png'

During handling of the above exception, another exception occurred:

Traceback (most recent call last):
  File "C:\Users\kth00\Documents\GitHub\2024_2_GameEngineBase\Team4\Content\Dataprocess\server.py", line 45, in predict
    prediction = predict_image(file_path)
  File "C:\Users\kth00\Documents\GitHub\2024_2_GameEngineBase\Team4\Content\Dataprocess\predict.py", line 36, in predict_image
    raise RuntimeError(f"Prediction failed: {e}")
RuntimeError: Prediction failed: [Errno 13] Permission denied: 'C:/Users/kth00/Documents/GitHub/2024_2_GameEngineBase/Team4/Saved/SavedDrawing.png'
2024-12-13 18:55:31,380 [INFO] 127.0.0.1 - - [13/Dec/2024 18:55:31] "[35m[1mPOST /predict HTTP/1.1[0m" 500 -
2024-12-13 18:55:31,432 [DEBUG] Received request: {'file_path': 'C:/Users/kth00/Documents/GitHub/2024_2_GameEngineBase/Team4/Saved/'}
2024-12-13 18:55:31,432 [INFO] File path received: C:/Users/kth00/Documents/GitHub/2024_2_GameEngineBase/Team4/Saved/SavedDrawing.png
2024-12-13 18:55:31,433 [INFO] Starting prediction...
2024-12-13 18:55:31,444 [ERROR] Error during prediction
Traceback (most recent call last):
  File "C:\Users\kth00\Documents\GitHub\2024_2_GameEngineBase\Team4\Content\Dataprocess\predict.py", line 23, in predict_image
    img = load_img(img_path, target_size=(224, 224))
  File "C:\Users\kth00\AppData\Local\Programs\Python\Python39\lib\site-packages\keras\utils\image_utils.py", line 422, in load_img
    with open(path, "rb") as f:
PermissionError: [Errno 13] Permission denied: 'C:/Users/kth00/Documents/GitHub/2024_2_GameEngineBase/Team4/Saved/SavedDrawing.png'

During handling of the above exception, another exception occurred:

Traceback (most recent call last):
  File "C:\Users\kth00\Documents\GitHub\2024_2_GameEngineBase\Team4\Content\Dataprocess\server.py", line 45, in predict
    prediction = predict_image(file_path)
  File "C:\Users\kth00\Documents\GitHub\2024_2_GameEngineBase\Team4\Content\Dataprocess\predict.py", line 36, in predict_image
    raise RuntimeError(f"Prediction failed: {e}")
RuntimeError: Prediction failed: [Errno 13] Permission denied: 'C:/Users/kth00/Documents/GitHub/2024_2_GameEngineBase/Team4/Saved/SavedDrawing.png'
2024-12-13 18:55:31,446 [INFO] 127.0.0.1 - - [13/Dec/2024 18:55:31] "[35m[1mPOST /predict HTTP/1.1[0m" 500 -
2024-12-13 18:55:31,499 [DEBUG] Received request: {'file_path': 'C:/Users/kth00/Documents/GitHub/2024_2_GameEngineBase/Team4/Saved/'}
2024-12-13 18:55:31,500 [INFO] File path received: C:/Users/kth00/Documents/GitHub/2024_2_GameEngineBase/Team4/Saved/SavedDrawing.png
2024-12-13 18:55:31,500 [INFO] Starting prediction...
2024-12-13 18:55:31,515 [DEBUG] STREAM b'IHDR' 16 13
2024-12-13 18:55:31,515 [DEBUG] STREAM b'IDAT' 41 8192
2024-12-13 18:55:31,541 [INFO] Prediction result: T
2024-12-13 18:55:31,542 [INFO] 127.0.0.1 - - [13/Dec/2024 18:55:31] "POST /predict HTTP/1.1" 200 -
2024-12-13 18:56:52,027 [INFO] [31m[1mWARNING: This is a development server. Do not use it in a production deployment. Use a production WSGI server instead.[0m
 * Running on http://127.0.0.1:8000
2024-12-13 18:56:52,028 [INFO] [33mPress CTRL+C to quit[0m
2024-12-13 18:56:52,031 [INFO]  * Restarting with stat
2024-12-13 18:56:55,040 [WARNING]  * Debugger is active!
2024-12-13 18:56:55,045 [INFO]  * Debugger PIN: 623-265-763
2024-12-13 18:57:06,773 [DEBUG] Received request: {'file_path': 'C:/Users/kth00/Documents/GitHub/2024_2_GameEngineBase/Team4/Saved/'}
2024-12-13 18:57:06,773 [INFO] File path received: C:/Users/kth00/Documents/GitHub/2024_2_GameEngineBase/Team4/Saved/SavedDrawing.png
2024-12-13 18:57:06,773 [INFO] Starting prediction...
2024-12-13 18:57:06,787 [ERROR] Error during prediction
Traceback (most recent call last):
  File "C:\Users\kth00\Documents\GitHub\2024_2_GameEngineBase\Team4\Dataprocess\predict.py", line 23, in predict_image
    img = load_img(img_path, target_size=(224, 224))
  File "C:\Users\kth00\AppData\Local\Programs\Python\Python39\lib\site-packages\keras\utils\image_utils.py", line 422, in load_img
    with open(path, "rb") as f:
PermissionError: [Errno 13] Permission denied: 'C:/Users/kth00/Documents/GitHub/2024_2_GameEngineBase/Team4/Saved/SavedDrawing.png'

During handling of the above exception, another exception occurred:

Traceback (most recent call last):
  File "C:\Users\kth00\Documents\GitHub\2024_2_GameEngineBase\Team4\Dataprocess\server.py", line 45, in predict
    prediction = predict_image(file_path)
  File "C:\Users\kth00\Documents\GitHub\2024_2_GameEngineBase\Team4\Dataprocess\predict.py", line 36, in predict_image
    raise RuntimeError(f"Prediction failed: {e}")
RuntimeError: Prediction failed: [Errno 13] Permission denied: 'C:/Users/kth00/Documents/GitHub/2024_2_GameEngineBase/Team4/Saved/SavedDrawing.png'
2024-12-13 18:57:06,793 [INFO] 127.0.0.1 - - [13/Dec/2024 18:57:06] "[35m[1mPOST /predict HTTP/1.1[0m" 500 -
2024-12-13 18:57:06,839 [DEBUG] Received request: {'file_path': 'C:/Users/kth00/Documents/GitHub/2024_2_GameEngineBase/Team4/Saved/'}
2024-12-13 18:57:06,839 [INFO] File path received: C:/Users/kth00/Documents/GitHub/2024_2_GameEngineBase/Team4/Saved/SavedDrawing.png
2024-12-13 18:57:06,839 [INFO] Starting prediction...
2024-12-13 18:57:06,853 [ERROR] Error during prediction
Traceback (most recent call last):
  File "C:\Users\kth00\Documents\GitHub\2024_2_GameEngineBase\Team4\Dataprocess\predict.py", line 23, in predict_image
    img = load_img(img_path, target_size=(224, 224))
  File "C:\Users\kth00\AppData\Local\Programs\Python\Python39\lib\site-packages\keras\utils\image_utils.py", line 422, in load_img
    with open(path, "rb") as f:
PermissionError: [Errno 13] Permission denied: 'C:/Users/kth00/Documents/GitHub/2024_2_GameEngineBase/Team4/Saved/SavedDrawing.png'

During handling of the above exception, another exception occurred:

Traceback (most recent call last):
  File "C:\Users\kth00\Documents\GitHub\2024_2_GameEngineBase\Team4\Dataprocess\server.py", line 45, in predict
    prediction = predict_image(file_path)
  File "C:\Users\kth00\Documents\GitHub\2024_2_GameEngineBase\Team4\Dataprocess\predict.py", line 36, in predict_image
    raise RuntimeError(f"Prediction failed: {e}")
RuntimeError: Prediction failed: [Errno 13] Permission denied: 'C:/Users/kth00/Documents/GitHub/2024_2_GameEngineBase/Team4/Saved/SavedDrawing.png'
2024-12-13 18:57:06,855 [INFO] 127.0.0.1 - - [13/Dec/2024 18:57:06] "[35m[1mPOST /predict HTTP/1.1[0m" 500 -
2024-12-13 18:57:06,871 [DEBUG] Received request: {'file_path': 'C:/Users/kth00/Documents/GitHub/2024_2_GameEngineBase/Team4/Saved/'}
2024-12-13 18:57:06,872 [INFO] File path received: C:/Users/kth00/Documents/GitHub/2024_2_GameEngineBase/Team4/Saved/SavedDrawing.png
2024-12-13 18:57:06,872 [INFO] Starting prediction...
2024-12-13 18:57:06,909 [DEBUG] STREAM b'IHDR' 16 13
2024-12-13 18:57:06,910 [DEBUG] STREAM b'IDAT' 41 8192
2024-12-13 18:57:06,940 [INFO] Prediction result: K
2024-12-13 18:57:06,940 [INFO] 127.0.0.1 - - [13/Dec/2024 18:57:06] "POST /predict HTTP/1.1" 200 -
2024-12-13 19:00:16,088 [DEBUG] Received request: {'file_path': 'C:/Users/kth00/Documents/GitHub/2024_2_GameEngineBase/Team4/exe/Windows/Saved'}
2024-12-13 19:00:16,089 [INFO] File path received: C:/Users/kth00/Documents/GitHub/2024_2_GameEngineBase/Team4/exe/Windows/SavedSavedDrawing.png
2024-12-13 19:00:16,089 [ERROR] File not found at C:/Users/kth00/Documents/GitHub/2024_2_GameEngineBase/Team4/exe/Windows/SavedSavedDrawing.png
2024-12-13 19:00:16,089 [INFO] 127.0.0.1 - - [13/Dec/2024 19:00:16] "[31m[1mPOST /predict HTTP/1.1[0m" 400 -
2024-12-13 19:00:16,123 [DEBUG] Received request: {'file_path': 'C:/Users/kth00/Documents/GitHub/2024_2_GameEngineBase/Team4/exe/Windows/Saved'}
2024-12-13 19:00:16,123 [INFO] File path received: C:/Users/kth00/Documents/GitHub/2024_2_GameEngineBase/Team4/exe/Windows/SavedSavedDrawing.png
2024-12-13 19:00:16,123 [ERROR] File not found at C:/Users/kth00/Documents/GitHub/2024_2_GameEngineBase/Team4/exe/Windows/SavedSavedDrawing.png
2024-12-13 19:00:16,123 [INFO] 127.0.0.1 - - [13/Dec/2024 19:00:16] "[31m[1mPOST /predict HTTP/1.1[0m" 400 -
2024-12-13 19:00:16,189 [DEBUG] Received request: {'file_path': 'C:/Users/kth00/Documents/GitHub/2024_2_GameEngineBase/Team4/exe/Windows/Saved'}
2024-12-13 19:00:16,189 [INFO] File path received: C:/Users/kth00/Documents/GitHub/2024_2_GameEngineBase/Team4/exe/Windows/SavedSavedDrawing.png
2024-12-13 19:00:16,190 [ERROR] File not found at C:/Users/kth00/Documents/GitHub/2024_2_GameEngineBase/Team4/exe/Windows/SavedSavedDrawing.png
2024-12-13 19:00:16,190 [INFO] 127.0.0.1 - - [13/Dec/2024 19:00:16] "[31m[1mPOST /predict HTTP/1.1[0m" 400 -
2024-12-13 19:00:17,295 [DEBUG] Received request: {'file_path': 'C:/Users/kth00/Documents/GitHub/2024_2_GameEngineBase/Team4/exe/Windows/Saved'}
2024-12-13 19:00:17,296 [INFO] File path received: C:/Users/kth00/Documents/GitHub/2024_2_GameEngineBase/Team4/exe/Windows/SavedSavedDrawing.png
2024-12-13 19:00:17,296 [ERROR] File not found at C:/Users/kth00/Documents/GitHub/2024_2_GameEngineBase/Team4/exe/Windows/SavedSavedDrawing.png
2024-12-13 19:00:17,296 [INFO] 127.0.0.1 - - [13/Dec/2024 19:00:17] "[31m[1mPOST /predict HTTP/1.1[0m" 400 -
2024-12-13 19:00:17,309 [DEBUG] Received request: {'file_path': 'C:/Users/kth00/Documents/GitHub/2024_2_GameEngineBase/Team4/exe/Windows/Saved'}
2024-12-13 19:00:17,309 [INFO] File path received: C:/Users/kth00/Documents/GitHub/2024_2_GameEngineBase/Team4/exe/Windows/SavedSavedDrawing.png
2024-12-13 19:00:17,310 [ERROR] File not found at C:/Users/kth00/Documents/GitHub/2024_2_GameEngineBase/Team4/exe/Windows/SavedSavedDrawing.png
2024-12-13 19:00:17,310 [INFO] 127.0.0.1 - - [13/Dec/2024 19:00:17] "[31m[1mPOST /predict HTTP/1.1[0m" 400 -
2024-12-13 19:00:17,362 [DEBUG] Received request: {'file_path': 'C:/Users/kth00/Documents/GitHub/2024_2_GameEngineBase/Team4/exe/Windows/Saved'}
2024-12-13 19:00:17,362 [INFO] File path received: C:/Users/kth00/Documents/GitHub/2024_2_GameEngineBase/Team4/exe/Windows/SavedSavedDrawing.png
2024-12-13 19:00:17,363 [ERROR] File not found at C:/Users/kth00/Documents/GitHub/2024_2_GameEngineBase/Team4/exe/Windows/SavedSavedDrawing.png
2024-12-13 19:00:17,363 [INFO] 127.0.0.1 - - [13/Dec/2024 19:00:17] "[31m[1mPOST /predict HTTP/1.1[0m" 400 -
2024-12-13 19:00:17,429 [DEBUG] Received request: {'file_path': 'C:/Users/kth00/Documents/GitHub/2024_2_GameEngineBase/Team4/exe/Windows/Saved'}
2024-12-13 19:00:17,431 [INFO] File path received: C:/Users/kth00/Documents/GitHub/2024_2_GameEngineBase/Team4/exe/Windows/SavedSavedDrawing.png
2024-12-13 19:00:17,431 [ERROR] File not found at C:/Users/kth00/Documents/GitHub/2024_2_GameEngineBase/Team4/exe/Windows/SavedSavedDrawing.png
2024-12-13 19:00:17,431 [INFO] 127.0.0.1 - - [13/Dec/2024 19:00:17] "[31m[1mPOST /predict HTTP/1.1[0m" 400 -
2024-12-13 19:00:33,410 [DEBUG] Received request: {'file_path': 'C:/Users/kth00/Documents/GitHub/2024_2_GameEngineBase/Team4/exe/Windows/Saved'}
2024-12-13 19:00:33,411 [INFO] File path received: C:/Users/kth00/Documents/GitHub/2024_2_GameEngineBase/Team4/exe/Windows/SavedSavedDrawing.png
2024-12-13 19:00:33,411 [ERROR] File not found at C:/Users/kth00/Documents/GitHub/2024_2_GameEngineBase/Team4/exe/Windows/SavedSavedDrawing.png
2024-12-13 19:00:33,411 [INFO] 127.0.0.1 - - [13/Dec/2024 19:00:33] "[31m[1mPOST /predict HTTP/1.1[0m" 400 -
2024-12-13 19:00:33,479 [DEBUG] Received request: {'file_path': 'C:/Users/kth00/Documents/GitHub/2024_2_GameEngineBase/Team4/exe/Windows/Saved'}
2024-12-13 19:00:33,479 [INFO] File path received: C:/Users/kth00/Documents/GitHub/2024_2_GameEngineBase/Team4/exe/Windows/SavedSavedDrawing.png
2024-12-13 19:00:33,480 [ERROR] File not found at C:/Users/kth00/Documents/GitHub/2024_2_GameEngineBase/Team4/exe/Windows/SavedSavedDrawing.png
2024-12-13 19:00:33,480 [INFO] 127.0.0.1 - - [13/Dec/2024 19:00:33] "[31m[1mPOST /predict HTTP/1.1[0m" 400 -
2024-12-13 19:00:33,511 [DEBUG] Received request: {'file_path': 'C:/Users/kth00/Documents/GitHub/2024_2_GameEngineBase/Team4/exe/Windows/Saved'}
2024-12-13 19:00:33,512 [INFO] File path received: C:/Users/kth00/Documents/GitHub/2024_2_GameEngineBase/Team4/exe/Windows/SavedSavedDrawing.png
2024-12-13 19:00:33,512 [ERROR] File not found at C:/Users/kth00/Documents/GitHub/2024_2_GameEngineBase/Team4/exe/Windows/SavedSavedDrawing.png
2024-12-13 19:00:33,512 [INFO] 127.0.0.1 - - [13/Dec/2024 19:00:33] "[31m[1mPOST /predict HTTP/1.1[0m" 400 -
2024-12-13 19:00:33,579 [DEBUG] Received request: {'file_path': 'C:/Users/kth00/Documents/GitHub/2024_2_GameEngineBase/Team4/exe/Windows/Saved'}
2024-12-13 19:00:33,579 [INFO] File path received: C:/Users/kth00/Documents/GitHub/2024_2_GameEngineBase/Team4/exe/Windows/SavedSavedDrawing.png
2024-12-13 19:00:33,580 [ERROR] File not found at C:/Users/kth00/Documents/GitHub/2024_2_GameEngineBase/Team4/exe/Windows/SavedSavedDrawing.png
2024-12-13 19:00:33,580 [INFO] 127.0.0.1 - - [13/Dec/2024 19:00:33] "[31m[1mPOST /predict HTTP/1.1[0m" 400 -
2024-12-13 19:01:22,533 [DEBUG] Received request: {'file_path': 'C:/Users/kth00/Documents/GitHub/2024_2_GameEngineBase/Team4/exe/Windows/Saved'}
2024-12-13 19:01:22,533 [INFO] File path received: C:/Users/kth00/Documents/GitHub/2024_2_GameEngineBase/Team4/exe/Windows/SavedSavedDrawing.png
2024-12-13 19:01:22,534 [ERROR] File not found at C:/Users/kth00/Documents/GitHub/2024_2_GameEngineBase/Team4/exe/Windows/SavedSavedDrawing.png
2024-12-13 19:01:22,534 [INFO] 127.0.0.1 - - [13/Dec/2024 19:01:22] "[31m[1mPOST /predict HTTP/1.1[0m" 400 -
2024-12-13 19:01:22,601 [DEBUG] Received request: {'file_path': 'C:/Users/kth00/Documents/GitHub/2024_2_GameEngineBase/Team4/exe/Windows/Saved'}
2024-12-13 19:01:22,602 [INFO] File path received: C:/Users/kth00/Documents/GitHub/2024_2_GameEngineBase/Team4/exe/Windows/SavedSavedDrawing.png
2024-12-13 19:01:22,602 [ERROR] File not found at C:/Users/kth00/Documents/GitHub/2024_2_GameEngineBase/Team4/exe/Windows/SavedSavedDrawing.png
2024-12-13 19:01:22,602 [INFO] 127.0.0.1 - - [13/Dec/2024 19:01:22] "[31m[1mPOST /predict HTTP/1.1[0m" 400 -
2024-12-13 19:07:49,653 [INFO] [31m[1mWARNING: This is a development server. Do not use it in a production deployment. Use a production WSGI server instead.[0m
 * Running on http://127.0.0.1:8000
2024-12-13 19:07:49,653 [INFO] [33mPress CTRL+C to quit[0m
2024-12-13 19:07:49,655 [INFO]  * Restarting with stat
2024-12-13 19:07:52,745 [WARNING]  * Debugger is active!
2024-12-13 19:07:52,748 [INFO]  * Debugger PIN: 623-265-763
2024-12-13 19:08:07,957 [DEBUG] Received request: {'file_path': 'C:/Users/kth00/Documents/GitHub/2024_2_GameEngineBase/Team4/exe/Windows/Saved'}
2024-12-13 19:08:07,957 [INFO] File path received: C:/Users/kth00/Documents/GitHub/2024_2_GameEngineBase/Team4/exe/Windows/SavedSavedDrawing.png
2024-12-13 19:08:07,957 [ERROR] File not found at C:/Users/kth00/Documents/GitHub/2024_2_GameEngineBase/Team4/exe/Windows/SavedSavedDrawing.png
2024-12-13 19:08:07,959 [INFO] 127.0.0.1 - - [13/Dec/2024 19:08:07] "[31m[1mPOST /predict HTTP/1.1[0m" 400 -
2024-12-13 19:08:26,860 [DEBUG] Received request: {'file_path': 'C:/Users/kth00/Documents/GitHub/2024_2_GameEngineBase/Team4/exe/Windows/Saved'}
2024-12-13 19:08:26,861 [INFO] File path received: C:/Users/kth00/Documents/GitHub/2024_2_GameEngineBase/Team4/exe/Windows/SavedSavedDrawing.png
2024-12-13 19:08:26,861 [ERROR] File not found at C:/Users/kth00/Documents/GitHub/2024_2_GameEngineBase/Team4/exe/Windows/SavedSavedDrawing.png
2024-12-13 19:08:26,861 [INFO] 127.0.0.1 - - [13/Dec/2024 19:08:26] "[31m[1mPOST /predict HTTP/1.1[0m" 400 -
2024-12-13 19:08:26,894 [DEBUG] Received request: {'file_path': 'C:/Users/kth00/Documents/GitHub/2024_2_GameEngineBase/Team4/exe/Windows/Saved'}
2024-12-13 19:08:26,894 [INFO] File path received: C:/Users/kth00/Documents/GitHub/2024_2_GameEngineBase/Team4/exe/Windows/SavedSavedDrawing.png
2024-12-13 19:08:26,895 [ERROR] File not found at C:/Users/kth00/Documents/GitHub/2024_2_GameEngineBase/Team4/exe/Windows/SavedSavedDrawing.png
2024-12-13 19:08:26,895 [INFO] 127.0.0.1 - - [13/Dec/2024 19:08:26] "[31m[1mPOST /predict HTTP/1.1[0m" 400 -
2024-12-13 19:08:38,644 [INFO] [31m[1mWARNING: This is a development server. Do not use it in a production deployment. Use a production WSGI server instead.[0m
 * Running on http://127.0.0.1:8000
2024-12-13 19:08:38,645 [INFO] [33mPress CTRL+C to quit[0m
2024-12-13 19:08:38,647 [INFO]  * Restarting with stat
2024-12-13 19:08:42,157 [WARNING]  * Debugger is active!
2024-12-13 19:08:42,160 [INFO]  * Debugger PIN: 623-265-763
2024-12-13 19:08:42,173 [DEBUG] Received request: {'file_path': 'C:/Users/kth00/Documents/GitHub/2024_2_GameEngineBase/Team4/exe/Windows/Saved'}
2024-12-13 19:08:42,174 [INFO] File path received: C:/Users/kth00/Documents/GitHub/2024_2_GameEngineBase/Team4/exe/Windows/SavedSavedDrawing.png
2024-12-13 19:08:42,175 [ERROR] File not found at C:/Users/kth00/Documents/GitHub/2024_2_GameEngineBase/Team4/exe/Windows/SavedSavedDrawing.png
2024-12-13 19:08:42,175 [INFO] 127.0.0.1 - - [13/Dec/2024 19:08:42] "[31m[1mPOST /predict HTTP/1.1[0m" 400 -
2024-12-13 19:14:46,330 [DEBUG] Received request: {'file_path': 'C:/Users/kth00/Documents/GitHub/2024_2_GameEngineBase/Team4/exe/Windows//Saved'}
2024-12-13 19:14:46,331 [INFO] File path received: C:/Users/kth00/Documents/GitHub/2024_2_GameEngineBase/Team4/exe/Windows//SavedSavedDrawing.png
2024-12-13 19:14:46,331 [ERROR] File not found at C:/Users/kth00/Documents/GitHub/2024_2_GameEngineBase/Team4/exe/Windows//SavedSavedDrawing.png
2024-12-13 19:14:46,331 [INFO] 127.0.0.1 - - [13/Dec/2024 19:14:46] "[31m[1mPOST /predict HTTP/1.1[0m" 400 -
2024-12-13 19:17:33,937 [INFO] [31m[1mWARNING: This is a development server. Do not use it in a production deployment. Use a production WSGI server instead.[0m
 * Running on http://127.0.0.1:8000
2024-12-13 19:17:33,938 [INFO] [33mPress CTRL+C to quit[0m
2024-12-13 19:17:33,940 [INFO]  * Restarting with stat
2024-12-13 19:17:37,439 [WARNING]  * Debugger is active!
2024-12-13 19:17:37,442 [INFO]  * Debugger PIN: 623-265-763
2024-12-13 19:18:27,040 [DEBUG] Received request: {'file_path': 'C:/Users/kth00/Documents/GitHub/2024_2_GameEngineBase/Team4/exe/Windows/Saved'}
2024-12-13 19:18:27,040 [INFO] File path received: C:/Users/kth00/Documents/GitHub/2024_2_GameEngineBase/Team4/exe/Windows/SavedSavedDrawing.png
2024-12-13 19:18:27,040 [ERROR] File not found at C:/Users/kth00/Documents/GitHub/2024_2_GameEngineBase/Team4/exe/Windows/SavedSavedDrawing.png
2024-12-13 19:18:27,041 [INFO] 127.0.0.1 - - [13/Dec/2024 19:18:27] "[31m[1mPOST /predict HTTP/1.1[0m" 400 -
2024-12-13 19:18:27,106 [DEBUG] Received request: {'file_path': 'C:/Users/kth00/Documents/GitHub/2024_2_GameEngineBase/Team4/exe/Windows/Saved'}
2024-12-13 19:18:27,106 [INFO] File path received: C:/Users/kth00/Documents/GitHub/2024_2_GameEngineBase/Team4/exe/Windows/SavedSavedDrawing.png
2024-12-13 19:18:27,106 [ERROR] File not found at C:/Users/kth00/Documents/GitHub/2024_2_GameEngineBase/Team4/exe/Windows/SavedSavedDrawing.png
2024-12-13 19:18:27,107 [INFO] 127.0.0.1 - - [13/Dec/2024 19:18:27] "[31m[1mPOST /predict HTTP/1.1[0m" 400 -
2024-12-13 19:25:48,929 [DEBUG] Received request: {'file_path': 'C:/Users/kth00/Documents/GitHub/2024_2_GameEngineBase/Team4/exe/Windows/'}
2024-12-13 19:25:48,929 [INFO] File path received: C:/Users/kth00/Documents/GitHub/2024_2_GameEngineBase/Team4/exe/Windows/SavedDrawing.png
2024-12-13 19:25:48,929 [INFO] Starting prediction...
2024-12-13 19:25:48,960 [ERROR] Error during prediction
Traceback (most recent call last):
  File "C:\Users\kth00\Documents\GitHub\2024_2_GameEngineBase\Team4\Dataprocess\predict.py", line 23, in predict_image
    img = load_img(img_path, target_size=(224, 224))
  File "C:\Users\kth00\AppData\Local\Programs\Python\Python39\lib\site-packages\keras\utils\image_utils.py", line 422, in load_img
    with open(path, "rb") as f:
PermissionError: [Errno 13] Permission denied: 'C:/Users/kth00/Documents/GitHub/2024_2_GameEngineBase/Team4/exe/Windows/SavedDrawing.png'

During handling of the above exception, another exception occurred:

Traceback (most recent call last):
  File "C:\Users\kth00\Documents\GitHub\2024_2_GameEngineBase\Team4\Dataprocess\server.py", line 45, in predict
    prediction = predict_image(file_path)
  File "C:\Users\kth00\Documents\GitHub\2024_2_GameEngineBase\Team4\Dataprocess\predict.py", line 36, in predict_image
    raise RuntimeError(f"Prediction failed: {e}")
RuntimeError: Prediction failed: [Errno 13] Permission denied: 'C:/Users/kth00/Documents/GitHub/2024_2_GameEngineBase/Team4/exe/Windows/SavedDrawing.png'
2024-12-13 19:25:48,982 [INFO] 127.0.0.1 - - [13/Dec/2024 19:25:48] "[35m[1mPOST /predict HTTP/1.1[0m" 500 -
2024-12-13 19:25:48,982 [DEBUG] Received request: {'file_path': 'C:/Users/kth00/Documents/GitHub/2024_2_GameEngineBase/Team4/exe/Windows/'}
2024-12-13 19:25:48,982 [INFO] File path received: C:/Users/kth00/Documents/GitHub/2024_2_GameEngineBase/Team4/exe/Windows/SavedDrawing.png
2024-12-13 19:25:48,983 [INFO] Starting prediction...
2024-12-13 19:25:48,997 [ERROR] Error during prediction
Traceback (most recent call last):
  File "C:\Users\kth00\Documents\GitHub\2024_2_GameEngineBase\Team4\Dataprocess\predict.py", line 23, in predict_image
    img = load_img(img_path, target_size=(224, 224))
  File "C:\Users\kth00\AppData\Local\Programs\Python\Python39\lib\site-packages\keras\utils\image_utils.py", line 422, in load_img
    with open(path, "rb") as f:
PermissionError: [Errno 13] Permission denied: 'C:/Users/kth00/Documents/GitHub/2024_2_GameEngineBase/Team4/exe/Windows/SavedDrawing.png'

During handling of the above exception, another exception occurred:

Traceback (most recent call last):
  File "C:\Users\kth00\Documents\GitHub\2024_2_GameEngineBase\Team4\Dataprocess\server.py", line 45, in predict
    prediction = predict_image(file_path)
  File "C:\Users\kth00\Documents\GitHub\2024_2_GameEngineBase\Team4\Dataprocess\predict.py", line 36, in predict_image
    raise RuntimeError(f"Prediction failed: {e}")
RuntimeError: Prediction failed: [Errno 13] Permission denied: 'C:/Users/kth00/Documents/GitHub/2024_2_GameEngineBase/Team4/exe/Windows/SavedDrawing.png'
2024-12-13 19:25:49,000 [INFO] 127.0.0.1 - - [13/Dec/2024 19:25:49] "[35m[1mPOST /predict HTTP/1.1[0m" 500 -
2024-12-13 19:25:49,048 [DEBUG] Received request: {'file_path': 'C:/Users/kth00/Documents/GitHub/2024_2_GameEngineBase/Team4/exe/Windows/'}
2024-12-13 19:25:49,049 [INFO] File path received: C:/Users/kth00/Documents/GitHub/2024_2_GameEngineBase/Team4/exe/Windows/SavedDrawing.png
2024-12-13 19:25:49,049 [INFO] Starting prediction...
2024-12-13 19:25:49,135 [DEBUG] STREAM b'IHDR' 16 13
2024-12-13 19:25:49,136 [DEBUG] STREAM b'IDAT' 41 8192
2024-12-13 19:25:49,176 [INFO] Prediction result: K
2024-12-13 19:25:49,176 [INFO] 127.0.0.1 - - [13/Dec/2024 19:25:49] "POST /predict HTTP/1.1" 200 -
2024-12-13 19:25:52,942 [DEBUG] Received request: {'file_path': 'C:/Users/kth00/Documents/GitHub/2024_2_GameEngineBase/Team4/exe/Windows/'}
2024-12-13 19:25:52,943 [INFO] File path received: C:/Users/kth00/Documents/GitHub/2024_2_GameEngineBase/Team4/exe/Windows/SavedDrawing.png
2024-12-13 19:25:52,943 [INFO] Starting prediction...
2024-12-13 19:25:52,960 [ERROR] Error during prediction
Traceback (most recent call last):
  File "C:\Users\kth00\Documents\GitHub\2024_2_GameEngineBase\Team4\Dataprocess\predict.py", line 23, in predict_image
    img = load_img(img_path, target_size=(224, 224))
  File "C:\Users\kth00\AppData\Local\Programs\Python\Python39\lib\site-packages\keras\utils\image_utils.py", line 422, in load_img
    with open(path, "rb") as f:
PermissionError: [Errno 13] Permission denied: 'C:/Users/kth00/Documents/GitHub/2024_2_GameEngineBase/Team4/exe/Windows/SavedDrawing.png'

During handling of the above exception, another exception occurred:

Traceback (most recent call last):
  File "C:\Users\kth00\Documents\GitHub\2024_2_GameEngineBase\Team4\Dataprocess\server.py", line 45, in predict
    prediction = predict_image(file_path)
  File "C:\Users\kth00\Documents\GitHub\2024_2_GameEngineBase\Team4\Dataprocess\predict.py", line 36, in predict_image
    raise RuntimeError(f"Prediction failed: {e}")
RuntimeError: Prediction failed: [Errno 13] Permission denied: 'C:/Users/kth00/Documents/GitHub/2024_2_GameEngineBase/Team4/exe/Windows/SavedDrawing.png'
2024-12-13 19:25:52,963 [INFO] 127.0.0.1 - - [13/Dec/2024 19:25:52] "[35m[1mPOST /predict HTTP/1.1[0m" 500 -
2024-12-13 19:25:53,010 [DEBUG] Received request: {'file_path': 'C:/Users/kth00/Documents/GitHub/2024_2_GameEngineBase/Team4/exe/Windows/'}
2024-12-13 19:25:53,011 [INFO] File path received: C:/Users/kth00/Documents/GitHub/2024_2_GameEngineBase/Team4/exe/Windows/SavedDrawing.png
2024-12-13 19:25:53,011 [INFO] Starting prediction...
2024-12-13 19:25:53,030 [DEBUG] STREAM b'IHDR' 16 13
2024-12-13 19:25:53,030 [DEBUG] STREAM b'IDAT' 41 8192
2024-12-13 19:25:53,063 [INFO] Prediction result: K
2024-12-13 19:25:53,063 [INFO] 127.0.0.1 - - [13/Dec/2024 19:25:53] "POST /predict HTTP/1.1" 200 -
2024-12-13 19:27:05,397 [DEBUG] Received request: {'file_path': 'C:/Users/kth00/Documents/GitHub/2024_2_GameEngineBase/Team4/exe/Windows/'}
2024-12-13 19:27:05,399 [INFO] File path received: C:/Users/kth00/Documents/GitHub/2024_2_GameEngineBase/Team4/exe/Windows/SavedDrawing.png
2024-12-13 19:27:05,400 [INFO] Starting prediction...
2024-12-13 19:27:05,421 [ERROR] Error during prediction
Traceback (most recent call last):
  File "C:\Users\kth00\Documents\GitHub\2024_2_GameEngineBase\Team4\Dataprocess\predict.py", line 23, in predict_image
    img = load_img(img_path, target_size=(224, 224))
  File "C:\Users\kth00\AppData\Local\Programs\Python\Python39\lib\site-packages\keras\utils\image_utils.py", line 422, in load_img
    with open(path, "rb") as f:
PermissionError: [Errno 13] Permission denied: 'C:/Users/kth00/Documents/GitHub/2024_2_GameEngineBase/Team4/exe/Windows/SavedDrawing.png'

During handling of the above exception, another exception occurred:

Traceback (most recent call last):
  File "C:\Users\kth00\Documents\GitHub\2024_2_GameEngineBase\Team4\Dataprocess\server.py", line 45, in predict
    prediction = predict_image(file_path)
  File "C:\Users\kth00\Documents\GitHub\2024_2_GameEngineBase\Team4\Dataprocess\predict.py", line 36, in predict_image
    raise RuntimeError(f"Prediction failed: {e}")
RuntimeError: Prediction failed: [Errno 13] Permission denied: 'C:/Users/kth00/Documents/GitHub/2024_2_GameEngineBase/Team4/exe/Windows/SavedDrawing.png'
2024-12-13 19:27:05,425 [INFO] 127.0.0.1 - - [13/Dec/2024 19:27:05] "[35m[1mPOST /predict HTTP/1.1[0m" 500 -
2024-12-13 19:27:05,472 [DEBUG] Received request: {'file_path': 'C:/Users/kth00/Documents/GitHub/2024_2_GameEngineBase/Team4/exe/Windows/'}
2024-12-13 19:27:05,472 [INFO] File path received: C:/Users/kth00/Documents/GitHub/2024_2_GameEngineBase/Team4/exe/Windows/SavedDrawing.png
2024-12-13 19:27:05,473 [INFO] Starting prediction...
2024-12-13 19:27:05,491 [DEBUG] STREAM b'IHDR' 16 13
2024-12-13 19:27:05,491 [DEBUG] STREAM b'IDAT' 41 8192
2024-12-13 19:27:05,524 [INFO] Prediction result: K
2024-12-13 19:27:05,525 [INFO] 127.0.0.1 - - [13/Dec/2024 19:27:05] "POST /predict HTTP/1.1" 200 -
2024-12-13 19:27:30,968 [DEBUG] Received request: {'file_path': 'C:/Users/kth00/Documents/GitHub/2024_2_GameEngineBase/Team4/exe/Windows/'}
2024-12-13 19:27:30,969 [INFO] File path received: C:/Users/kth00/Documents/GitHub/2024_2_GameEngineBase/Team4/exe/Windows/SavedDrawing.png
2024-12-13 19:27:30,971 [INFO] Starting prediction...
2024-12-13 19:27:31,031 [DEBUG] STREAM b'IHDR' 16 13
2024-12-13 19:27:31,032 [DEBUG] STREAM b'IDAT' 41 8192
2024-12-13 19:27:31,046 [DEBUG] Received request: {'file_path': 'C:/Users/kth00/Documents/GitHub/2024_2_GameEngineBase/Team4/exe/Windows/'}
2024-12-13 19:27:31,047 [INFO] File path received: C:/Users/kth00/Documents/GitHub/2024_2_GameEngineBase/Team4/exe/Windows/SavedDrawing.png
2024-12-13 19:27:31,047 [INFO] Starting prediction...
2024-12-13 19:27:31,102 [DEBUG] STREAM b'IHDR' 16 13
2024-12-13 19:27:31,106 [DEBUG] STREAM b'IDAT' 41 8192
2024-12-13 19:27:31,179 [INFO] Prediction result: K
2024-12-13 19:27:31,181 [INFO] 127.0.0.1 - - [13/Dec/2024 19:27:31] "POST /predict HTTP/1.1" 200 -
2024-12-13 19:27:31,189 [INFO] Prediction result: K
2024-12-13 19:27:31,190 [INFO] 127.0.0.1 - - [13/Dec/2024 19:27:31] "POST /predict HTTP/1.1" 200 -
2024-12-13 19:28:25,560 [DEBUG] Received request: {'file_path': 'C:/Users/kth00/Documents/GitHub/2024_2_GameEngineBase/Team4/exe/Windows/'}
2024-12-13 19:28:25,561 [INFO] File path received: C:/Users/kth00/Documents/GitHub/2024_2_GameEngineBase/Team4/exe/Windows/SavedDrawing.png
2024-12-13 19:28:25,561 [INFO] Starting prediction...
2024-12-13 19:28:25,578 [ERROR] Error during prediction
Traceback (most recent call last):
  File "C:\Users\kth00\Documents\GitHub\2024_2_GameEngineBase\Team4\Dataprocess\predict.py", line 23, in predict_image
    img = load_img(img_path, target_size=(224, 224))
  File "C:\Users\kth00\AppData\Local\Programs\Python\Python39\lib\site-packages\keras\utils\image_utils.py", line 422, in load_img
    with open(path, "rb") as f:
PermissionError: [Errno 13] Permission denied: 'C:/Users/kth00/Documents/GitHub/2024_2_GameEngineBase/Team4/exe/Windows/SavedDrawing.png'

During handling of the above exception, another exception occurred:

Traceback (most recent call last):
  File "C:\Users\kth00\Documents\GitHub\2024_2_GameEngineBase\Team4\Dataprocess\server.py", line 45, in predict
    prediction = predict_image(file_path)
  File "C:\Users\kth00\Documents\GitHub\2024_2_GameEngineBase\Team4\Dataprocess\predict.py", line 36, in predict_image
    raise RuntimeError(f"Prediction failed: {e}")
RuntimeError: Prediction failed: [Errno 13] Permission denied: 'C:/Users/kth00/Documents/GitHub/2024_2_GameEngineBase/Team4/exe/Windows/SavedDrawing.png'
2024-12-13 19:28:25,580 [INFO] 127.0.0.1 - - [13/Dec/2024 19:28:25] "[35m[1mPOST /predict HTTP/1.1[0m" 500 -
2024-12-13 19:28:25,865 [DEBUG] Received request: {'file_path': 'C:/Users/kth00/Documents/GitHub/2024_2_GameEngineBase/Team4/exe/Windows/'}
2024-12-13 19:28:25,866 [INFO] File path received: C:/Users/kth00/Documents/GitHub/2024_2_GameEngineBase/Team4/exe/Windows/SavedDrawing.png
2024-12-13 19:28:25,867 [INFO] Starting prediction...
2024-12-13 19:28:25,902 [DEBUG] STREAM b'IHDR' 16 13
2024-12-13 19:28:25,903 [DEBUG] STREAM b'IDAT' 41 8192
2024-12-13 19:28:25,955 [INFO] Prediction result: K
2024-12-13 19:28:25,956 [INFO] 127.0.0.1 - - [13/Dec/2024 19:28:25] "POST /predict HTTP/1.1" 200 -
2024-12-13 21:48:50,317 [INFO] [31m[1mWARNING: This is a development server. Do not use it in a production deployment. Use a production WSGI server instead.[0m
 * Running on http://127.0.0.1:8000
2024-12-13 21:48:50,318 [INFO] [33mPress CTRL+C to quit[0m
2024-12-13 21:48:50,321 [INFO]  * Restarting with stat
2024-12-13 21:48:53,794 [WARNING]  * Debugger is active!
2024-12-13 21:48:53,800 [INFO]  * Debugger PIN: 623-265-763
2024-12-13 21:49:11,892 [DEBUG] Received request: {'file_path': 'C:/Users/kth00/Documents/GitHub/2024_2_GameEngineBase/Team4/Saved/'}
2024-12-13 21:49:11,893 [INFO] File path received: C:/Users/kth00/Documents/GitHub/2024_2_GameEngineBase/Team4/Saved/SavedDrawing.png
2024-12-13 21:49:11,893 [INFO] Starting prediction...
2024-12-13 21:49:11,945 [DEBUG] Received request: {'file_path': 'C:/Users/kth00/Documents/GitHub/2024_2_GameEngineBase/Team4/Saved/'}
2024-12-13 21:49:11,945 [INFO] File path received: C:/Users/kth00/Documents/GitHub/2024_2_GameEngineBase/Team4/Saved/SavedDrawing.png
2024-12-13 21:49:11,945 [INFO] Starting prediction...
2024-12-13 21:49:12,053 [DEBUG] STREAM b'IHDR' 16 13
2024-12-13 21:49:12,054 [DEBUG] STREAM b'IHDR' 16 13
2024-12-13 21:49:12,055 [DEBUG] STREAM b'IDAT' 41 8192
2024-12-13 21:49:12,055 [DEBUG] STREAM b'IDAT' 41 8192
2024-12-13 21:49:12,092 [INFO] Prediction result: T
2024-12-13 21:49:12,096 [INFO] Prediction result: T
2024-12-13 21:49:12,097 [INFO] 127.0.0.1 - - [13/Dec/2024 21:49:12] "POST /predict HTTP/1.1" 200 -
2024-12-13 21:49:12,098 [INFO] 127.0.0.1 - - [13/Dec/2024 21:49:12] "POST /predict HTTP/1.1" 200 -
